Workbook

Sheet #1. 재무상태표
A1: 재 무 상 태 표
A2: 제 8 기 2024년 12월 31일 현재
A3: 제 7 기 2023년 12월 31일 현재
A5: 서울교통공사 | I5: (단위 : 원)
B6: 과 목 | F6: 제 8 기 (2024.12.31.) | H6: 제 7 기 (2023.12.31.)
A7: 자 산
A8: Ⅰ. | B8: 유동자산 | G8: 644254172265 | I8: 634283639310 | L8: =F8/100 -> 0 | M8: =G8/100 -> 6.4425417e+09 | O8: =I8/100 -> 6.3428364e+09 | Q8: =M8-O8 -> 99705330
A9: (1) | C9: 당좌자산 | G9: 557662343563 | I9: 550079047284 | L9: =F9/100 -> 0 | M9: =G9/100 -> 5.5766234e+09 | N9: =H9/100 -> 0 | O9: =I9/100 -> 5.5007905e+09 | P9: =L9-N9 -> 0 | Q9: =M9-O9 -> 75832963
D10: 현금및현금성자산 | F10: 505424667593 | H10: 551033407060 | L10: =F10/100 -> 5.0542467e+09 | M10: =G10/100 -> 0 | N10: =H10/100 -> 5.5103341e+09 | O10: =I10/100 -> 0 | P10: =L10-N10 -> -4.5608739e+08 | Q10: =M10-O10 -> 0
D11: (정부보조금) | F11: -85898864984 | H11: -92047422948 | L11: =F11/100 -> -8.5898865e+08 | M11: =G11/100 -> 0 | N11: =H11/100 -> -9.2047423e+08 | O11: =I11/100 -> 0 | P11: =L11-N11 -> 61485580 | Q11: =M11-O11 -> 0
D12: (지자체보조금) | F12: -2447022885 | H12: -831504818 | L12: =F12/100 -> -24470229 | M12: =G12/100 -> 0 | N12: =H12/100 -> -8315048.2 | O12: =I12/100 -> 0 | P12: =L12-N12 -> -16155181 | Q12: =M12-O12 -> 0
D13: (수탁자산취득보조금) | F13: -9344151294 | H13: -6908541250 | L13: =F13/100 -> -93441513 | M13: =G13/100 -> 0 | N13: =H13/100 -> -69085412 | O13: =I13/100 -> 0 | P13: =L13-N13 -> -24356100 | Q13: =M13-O13 -> 0
D14: 단기금융상품 | F14: 0 | H14: 0 | L14: =F14/100 -> 0 | M14: =G14/100 -> 0 | N14: =H14/100 -> 0 | O14: =I14/100 -> 0 | P14: =L14-N14 -> 0 | Q14: =M14-O14 -> 0
D15: 단기대여금 | F15: 1341011674 | H15: 1224834050 | L15: =F15/100 -> 13410117 | M15: =G15/100 -> 0 | N15: =H15/100 -> 12248340 | O15: =I15/100 -> 0 | P15: =L15-N15 -> 1161776.2 | Q15: =M15-O15 -> 0
D16: 매출채권 | F16: 167517195603 | H16: 118402009024 | L16: =F16/100 -> 1.675172e+09 | M16: =G16/100 -> 0 | N16: =H16/100 -> 1.1840201e+09 | O16: =I16/100 -> 0 | P16: =L16-N16 -> 4.9115187e+08 | Q16: =M16-O16 -> 0
D17: (대손충당금) | F17: -33299162455 | H17: -29024573170 | L17: =F17/100 -> -3.3299162e+08 | M17: =G17/100 -> 0 | N17: =H17/100 -> -2.9024573e+08 | O17: =I17/100 -> 0 | P17: =L17-N17 -> -42745893 | Q17: =M17-O17 -> 0
D18: 미수금 | F18: 43218431794 | H18: 37217687792 | L18: =F18/100 -> 4.3218432e+08 | M18: =G18/100 -> 0 | N18: =H18/100 -> 3.7217688e+08 | O18: =I18/100 -> 0 | P18: =L18-N18 -> 60007440 | Q18: =M18-O18 -> 0
D19: (대손충당금) | F19: -34832030536 | H19: -34084890823 | L19: =F19/100 -> -3.4832031e+08 | M19: =G19/100 -> 0 | N19: =H19/100 -> -3.4084891e+08 | O19: =I19/100 -> 0 | P19: =L19-N19 -> -7471397.1 | Q19: =M19-O19 -> 0
D20: 미수수익 | F20: 698841011 | H20: 333053762 | L20: =F20/100 -> 6988410.1 | M20: =G20/100 -> 0 | N20: =H20/100 -> 3330537.6 | O20: =I20/100 -> 0 | P20: =L20-N20 -> 3657872.5 | Q20: =M20-O20 -> 0
D21: 선급금 | F21: 786595011 | H21: 379580278 | L21: =F21/100 -> 7865950.1 | M21: =G21/100 -> 0 | N21: =H21/100 -> 3795802.8 | O21: =I21/100 -> 0 | P21: =L21-N21 -> 4070147.3 | Q21: =M21-O21 -> 0
... D25: 기타의당좌자산 | F25: 1109344340 | H25: 1110234360 | L25: =F25/100 -> 11093443 | M25: =G25/100 -> 0 | N25: =H25/100 -> 11102344 | O25: =I25/100 -> 0 | P25: =L25-N25 -> -8900.2 | Q25: =M25-O25 -> 0
A26: (2) | C26: 재고자산 | G26: 86591828702 | I26: 84204592026 | L26: =F26/100 -> 0 | M26: =G26/100 -> 8.6591829e+08 | N26: =H26/100 -> 0 | O26: =I26/100 -> 8.4204592e+08 | P26: =L26-N26 -> 0 | Q26: =M26-O26 -> 23872367
D27: 저장품 | F27: 85531091203 | H27: 83379199213 | L27: =F27/100 -> 8.5531091e+08 | M27: =G27/100 -> 0 | N27: =H27/100 -> 8.3379199e+08 | O27: =I27/100 -> 0 | P27: =L27-N27 -> 21518920 | Q27: =M27-O27 -> 0
D28: 미착품 | F28: 1060737499 | H28: 825392813 | L28: =F28/100 -> 10607375 | M28: =G28/100 -> 0 | N28: =H28/100 -> 8253928.1 | O28: =I28/100 -> 0 | P28: =L28-N28 -> 2353446.9 | Q28: =M28-O28 -> 0
A29: Ⅱ. | B29: 비유동자산 | G29: 15159339038516 | I29: 15033291613809 | L29: =F29/100 -> 0 | M29: =G29/100 -> 1.5159339e+11 | N29: =H29/100 -> 0 | O29: =I29/100 -> 1.5033292e+11 | P29: =L29-N29 -> 0 | Q29: =M29-O29 -> 1.2604742e+09
A30: (1) | C30: 투자자산 | G30: 124267528297 | I30: 93430804361 | L30: =F30/100 -> 0 | M30: =G30/100 -> 1.2426753e+09 | N30: =H30/100 -> 0 | O30: =I30/100 -> 9.3430804e+08 | P30: =L30-N30 -> 0 | Q30: =M30-O30 -> 3.0836724e+08
D31: 매도가능증권 | F31: 527685720 | H31: 503257100 | L31: =F31/100 -> 5276857.2 | M31: =G31/100 -> 0 | N31: =H31/100 -> 5032571 | O31: =I31/100 -> 0 | P31: =L31-N31 -> 244286.2 | Q31: =M31-O31 -> 0
D32: 장기대여금 | F32: 46189308210 | H32: 49850573827 | L32: =F32/100 -> 4.6189308e+08 | M32: =G32/100 -> 0 | N32: =H32/100 -> 4.9850574e+08 | O32: =I32/100 -> 0 | P32: =L32-N32 -> -36612656 | Q32: =M32-O32 -> 0
D33: 지분법적용투자주식 | F33: 77550534367 | H33: 43076973434 | L33: =F33/100 -> 7.7550534e+08 | M33: =G33/100 -> 0 | N33: =H33/100 -> 4.3076973e+08 | O33: =I33/100 -> 0 | P33: =L33-N33 -> 3.4473561e+08 | Q33: =M33-O33 -> 0
C34: 4. | D34: 장기금융상품 | L34: =F34/100 -> 0 | M34: =G34/100 -> 0 | N34: =H34/100 -> 0 | O34: =I34/100 -> 0 | P34: =L34-N34 -> 0 | Q34: =M34-O34 -> 0
A35: (2) | C35: 유형자산 | G35: 14905617649144 | I35: 14808202023897 | L35: =F35/100 -> 0 | M35: =G35/100 -> 1.4905618e+11 | N35: =H35/100 -> 0 | O35: =I35/100 -> 1.4808202e+11 | P35: =L35-N35 -> 0 | Q35: =M35-O35 -> 9.7415625e+08
D36: 토지 | F36: 4858772779849 | H36: 4859347139849 | L36: =F36/100 -> 4.8587728e+10 | M36: =G36/100 -> 0 | N36: =H36/100 -> 4.8593471e+10 | O36: =I36/100 -> 0 | P36: =L36-N36 -> -5743600 | Q36: =M36-O36 -> 0
D37: 건물 | F37: 517357472055 | H37: 512305191446 | L37: =F37/100 -> 5.1735747e+09 | M37: =G37/100 -> 0 | N37: =H37/100 -> 5.1230519e+09 | O37: =I37/100 -> 0 | P37: =L37-N37 -> 50522806 | Q37: =M37-O37 -> 0
D38: (감가상각누계액) | F38: -345541442477 | H38: -336807939016 | L38: =F38/100 -> -3.4554144e+09 | M38: =G38/100 -> 0 | N38: =H38/100 -> -3.3680794e+09 | O38: =I38/100 -> 0 | P38: =L38-N38 -> -87335035 | Q38: =M38-O38 -> 0
D39: (정부보조금) | F39: -876142410 | H39: -836085236 | L39: =F39/100 -> -8761424.1 | M39: =G39/100 -> 0 | N39: =H39/100 -> -8360852.4 | O39: =I39/100 -> 0 | P39: =L39-N39 -> -400571.74 | Q39: =M39-O39 -> 0
D40: 기계장치 | F40: 105744995363 | H40: 103814389417 | L40: =F40/100 -> 1.05745e+09 | M40: =G40/100 -> 0 | N40: =H40/100 -> 1.0381439e+09 | O40: =I40/100 -> 0 | P40: =L40-N40 -> 19306059 | Q40: =M40-O40 -> 0
D41: (감가상각누계액) | F41: -65080335660 | H41: -62773853942 | L41: =F41/100 -> -6.5080336e+08 | M41: =G41/100 -> 0 | N41: =H41/100 -> -6.2773854e+08 | O41: =I41/100 -> 0 | P41: =L41-N41 -> -23064817 | Q41: =M41-O41 -> 0
D42: (정부보조금) | F42: -19627123 | H42: -23423123
D43: 선로설비 | F43: 12583143288195 | H43: 12443228689235 | L43: =F43/100 -> 1.2583143e+11 | M43: =G43/100 -> 0 | N43: =H43/100 -> 1.2443229e+11 | O43: =I43/100 -> 0 | P43: =L43-N43 -> 1.399146e+09 | Q43: =M43-O43 -> 0
D44: (감가상각누계액) | F44: -5614796049920 | H44: -5389750000975 | L44: =F44/100 -> -5.614796e+10 | M44: =G44/100 -> 0 | N44: =H44/100 -> -5.38975e+10 | O44: =I44/100 -> 0 | P44: =L44-N44 -> -2.2504605e+09 | Q44: =M44-O44 -> 0
...

Sheet #2. 손익계산서
A1: 손 익 계 산 서
A2: 제 8 기 2024년 1월 1일부터 2024년 12월 31일까지
A3: 제 7 기 2023년 1월 1일부터 2023년 12월 31일까지
A5: 서울교통공사 | I5: (단위 : 원)
B6: 과 목 | F6: 제 8 기 | H6: 제 7 기
A7: Ⅰ. | B7: 매출액 | G7: 2068192612476 | I7: 1870727392171 | K7: 영업수익 | L7: 총수익 | M7: =(G7+G50)/100 -> 2.4334807e+10 | N7: =(I7+I50)/100 -> 2.3222919e+10 | O7: =M7-N7 -> 1.1118885e+09 | P7: =G7/100 -> 2.0681926e+10 | Q7: =I7/100 -> 1.8707274e+10 | U7: =F7/100 -> 0 | V7: =G7/100 -> 2.0681926e+10 | W7: =H7/100 -> 0 | X7: =I7/100 -> 1.8707274e+10 | Z7: =U7-W7 -> 0 | AA7: =V7-X7 -> 1.9746522e+09
B8: 1. | C8: 운영사업수익 | G8: 1888104809216 | I8: 1777443369313 | K8: 운수사업수익 | L8: 총비용 | M8: =(G17+G24+G65)/100 -> 3.1576076e+10 | N8: =(I17+I24+I65)/100 -> 2.8395791e+10 | O8: =M8-N8 -> 3.1802846e+09 | P8: =F9/100 -> 1.5783652e+10 | Q8: =H9/100 -> 1.4725476e+10 | U8: =F8/100 -> 0 | V8: =G8/100 -> 1.8881048e+10 | W8: =H8/100 -> 0 | X8: =I8/100 -> 1.7774434e+10 | Z8: =U8-W8 -> 0 | AA8: =V8-X8 -> 1.1066144e+09
C9: (1) | D9: 운수사업수익 | F9: 1578365191559 | H9: 1472547565464 | K9: 부대사업수익 | L9: 순이익 | M9: =M7-M8 -> -7.2412685e+09 | N9: =N7-N8 -> -5.1728724e+09 | O9: =M9-N9 -> -2.068396e+09 | P9: =F10/100 -> 1.9352182e+09 | Q9: =H10/100 -> 1.9744802e+09 | U9: =F9/100 -> 1.5783652e+10 | V9: =G9/100 -> 0 | W9: =H9/100 -> 1.4725476e+10 | X9: =I9/100 -> 0 | Z9: =U9-W9 -> 1.0581763e+09 | AA9: =V9-X9 -> 0
C10: (2) | D10: 부대사업수익 | F10: 193521822246 | H10: 197448016699 | K10: 기타사업수익 | P10: =F11/100 -> 1.162178e+09 | Q10: =H11/100 -> 1.0744779e+09 | U10: =F10/100 -> 1.9352182e+09 | V10: =G10/100 -> 0 | W10: =H10/100 -> 1.9744802e+09 | X10: =I10/100 -> 0 | Z10: =U10-W10 -> -39261945 | AA10: =V10-X10 -> 0
C11: (3) | D11: 기타사업수익 | F11: 116217795411 | H11: 107447787150 | K11: 수탁사업수익 | P11: =G12/100 -> 1.800878e+09 | Q11: =I12/100 -> 9.3284023e+08 | U11: =F11/100 -> 1.162178e+09 | V11: =G11/100 -> 0 | W11: =H11/100 -> 1.0744779e+09 | X11: =I11/100 -> 0 | Z11: =U11-W11 -> 87700083 | AA11: =V11-X11 -> 0
B12: 2. | C12: 수탁사업수익 | G12: 180087803260 | I12: 93284022858 | U12: =F12/100 -> 0 | V12: =G12/100 -> 1.800878e+09 | W12: =H12/100 -> 0 | X12: =I12/100 -> 9.3284023e+08 | Z12: =U12-W12 -> 0 | AA12: =V12-X12 -> 8.680378e+08
C13: (1) | D13: 운수사업수익 | F13: 0 | H13: 0 | K13: 영업외수익 | P13: =G50/100 -> 3.6528812e+09 | Q13: =I50/100 -> 4.5156449e+09 | U13: =F13/100 -> 0 | V13: =G13/100 -> 0 | W13: =H13/100 -> 0 | X13: =I13/100 -> 0 | Z13: =U13-W13 -> 0 | AA13: =V13-X13 -> 0
C14: (2) | D14: 부대사업수익 | F14: 0 | H14: 0 | K14: 이자수익 | P14: =F51/100 -> 1.5291672e+08 | Q14: =H51/100 -> 1.1378563e+08 | U14: =F14/100 -> 0 | V14: =G14/100 -> 0 | W14: =H14/100 -> 0 | X14: =I14/100 -> 0 | Z14: =U14-W14 -> 0 | AA14: =V14-X14 -> 0
C15: (3) | D15: 기타사업수익 | F15: 0 | H15: 0 | K15: 자산수증이익 | P15: =F60/100 -> 1.00465e+08 | Q15: =H60/100 -> 5.5284292e+08 | U15: =F15/100 -> 0 | V15: =G15/100 -> 0 | W15: =H15/100 -> 0 | X15: =I15/100 -> 0 | Z15: =U15-W15 -> 0 | AA15: =V15-X15 -> 0
C16: 대행사업수익 | F16: 180087803260 | H16: 93284022858 | K16: 잡이익 | P16: =SUM(F54,F55,F63,F64)/100 -> 3.0819677e+09 | Q16: =SUM(#REF!,H55,H64,#REF!)/100 -> #REF! | U16: =F16/100 -> 1.800878e+09 | V16: =G16/100 -> 0 | W16: =H16/100 -> 9.3284023e+08 | X16: =I16/100 -> 0 | Z16: =U16-W16 -> 8.680378e+08 | AA16: =V16-X16 -> 0
A17: Ⅱ. | B17: 매출원가 | G17: 2869939304930 | I17: 2553455761808 | U17: =F17/100 -> 0 | V17: =G17/100 -> 2.8699393e+10 | W17: =H17/100 -> 0 | X17: =I17/100 -> 2.5534558e+10 | Z17: =U17-W17 -> 0 | AA17: =V17-X17 -> 3.1648354e+09
B18: 1. | C18: 운영사업원가 | F18: 2689851501670 | H18: 2460171738950 | U18: =F18/100 -> 2.6898515e+10 | V18: =G18/100 -> 0 | W18: =H18/100 -> 2.4601717e+10 | X18: =I18/100 -> 0 | Z18: =U18-W18 -> 2.2967976e+09 | AA18: =V18-X18 -> 0
B19: 2. | C19: 수탁사업원가 | F19: 180087803260 | H19: 93284022858 | K19: 영업비용 | P19: =(G17+G24)/100 -> 3.0136843e+10 | Q19: =(I17+I24)/100 -> 27159285361 | U19: =F19/100 -> 1.800878e+09 | V19: =G19/100 -> 0 | W19: =H19/100 -> 9.3284023e+08 | X19: =I19/100 -> 0 | Z19: =U19-W19 -> 8.680378e+08 | AA19: =V19-X19 -> 0
C20: (1) | D20: 7호선 연장구간 | U20: =F20/100 -> 0 | V20: =G20/100 -> 0 | W20: =H20/100 -> 0 | X20: =I20/100 -> 0 | Z20: =U20-W20 -> 0 | AA20: =V20-X20 -> 0
C21: (2) | D21: 9호선 2-3단계 운영 | U21: =F21/100 -> 0 | V21: =G21/100 -> 0 | W21: =H21/100 -> 0 | X21: =I21/100 -> 0 | Z21: =U21-W21 -> 0 | AA21: =V21-X21 -> 0
C22: (3) | D22: 잠실광역환승센터 | U22: =F22/100 -> 0 | V22: =G22/100 -> 0 | W22: =H22/100 -> 0 | X22: =I22/100 -> 0 | Z22: =U22-W22 -> 0 | AA22: =V22-X22 -> 0
A23: III. | B23: 매출총이익(손실) | G23: -801746692454 | I23: -682728369637 | K23: 인건비 | P23: =SUM('#3. 운영사업원가명세서'!F7,F25,F26)/100 -> 1.4205491e+10 | Q23: =SUM('#3. 운영사업원가명세서'!G8,'#3. 운영사업원가명세서'!G9,'#2. 손익계산서'!H25,'#2. 손익계산서'!H26)/100 -> 1.2202406e+10 | R23: =SUM('#3. 운영사업원가명세서'!F7,F25,F26)/100 -> 1.4205491e+10 | S23: =SUM('#3. 운영사업원가명세서'!G8,'#3. 운영사업원가명세서'!G9,'#2. 손익계산서'!H25,'#2. 손익계산서'!H26)/100 -> 1.2202406e+10 | U23: =F23/100 -> 0 | V23: =G23/100 -> -8.0174669e+09 | W23: =H23/100 -> 0 | X23: =I23/100 -> -6.8272837e+09 | Z23: =U23-W23 -> 0 | AA23: =V23-X23 -> -1.1901832e+09
A24: IV. | B24: 판매비와관리비 | G24: 143745027038 | I24: 162472774292 | K24: 경비 | P24: =SUM('#3. 운영사업원가명세서'!F10,'#2. 손익계산서'!F27:F48)/100 -> 1.4130474e+10 | Q24: =SUM('#3. 운영사업원가명세서'!H10,'#2. 손익계산서'!H27:H48)/100 -> 1.4024039e+10 | R24: =SUM('#3. 운영사업원가명세서'!F10,'#2. 손익계산서'!F27:F48)/100 -> 1.4130474e+10 | S24: =SUM('#3. 운영사업원가명세서'!H10,'#2. 손익계산서'!H27:H48)/100 -> 1.4024039e+10 | U24: =F24/100 -> 0 | V24: =G24/100 -> 1.4374503e+09 | W24: =H24/100 -> 0 | X24: =I24/100 -> 1.6247277e+09 | Z24: =U24-W24 -> 0 | AA24: =V24-X24 -> -1.8727747e+08
C25: 급여 | F25: 68940797557 | H25: 62563016685 | K25: 수탁원가 | P25: =F19/100 -> 1.800878e+09 | Q25: =H19/100 -> 9.3284023e+08 | U25: =F25/100 -> 6.8940798e+08 | V25: =G25/100 -> 0 | W25: =H25/100 -> 6.2563017e+08 | X25: =I25/100 -> 0 | Z25: =U25-W25 -> 63777809 | AA25: =V25-X25 -> 0
C26: 퇴직급여 | F26: 12268689630 | H26: 6259269090 | U26: =F26/100 -> 1.226869e+08 | V26: =G26/100 -> 0 | W26: =H26/100 -> 62592691 | X26: =I26/100 -> 0 | Z26: =U26-W26 -> 60094205 | AA26: =V26-X26 -> 0
C27: 복리후생비 | F27: 9841938088 | H27: 10082863973 | K27: 영업외비용 | P27: =G65/100 -> 1.4392325e+09 | Q27: =I65/100 -> 1.2365059e+09 | U27: =F27/100 -> 98419381 | V27: =G27/100 -> 0 | W27: =H27/100 -> 1.0082864e+08 | X27: =I27/100 -> 0 | Z27: =U27-W27 -> -2409258.9 | AA27: =V27-X27 -> 0
C28: 여비교통비 | F28: 133666778 | H28: 91237874 | K28: 이자비용 | P28: =F66/100 -> 1.3057433e+09 | Q28: =H66/100 -> 1.0538707e+09 | U28: =F28/100 -> 1336667.8 | V28: =G28/100 -> 0 | W28: =H28/100 -> 912378.74 | X28: =I28/100 -> 0 | Z28: =U28-W28 -> 424289.04 | AA28: =V28-X28 -> 0
C29: 공공요금및제세 | F29: 1983151298 | H29: 1428730770 | K29: 잡손실 | P29: =SUM(F67:F80)/100 -> 1.3348921e+08 | Q29: =SUM(H67:H80)/100 -> 1.8263517e+08 | U29: =F29/100 -> 19831513 | V29: =G29/100 -> 0 | W29: =H29/100 -> 14287308 | X29: =I29/100 -> 0 | Z29: =U29-W29 -> 5544205.3 | AA29: =V29-X29 -> 0
C30: 수도광열비 | F30: 269335206 | H30: 273506369 | U30: =F30/100 -> 2693352.1 | V30: =G30/100 -> 0 | W30: =H30/100 -> 2735063.7 | X30: =I30/100 -> 0 | Z30: =U30-W30 -> -41711.63 | AA30: =V30-X30 -> 0
C31: 소모품비 | F31: 305343623 | H31: 196233500 | U31: =F31/100 -> 3053436.2 | V31: =G31/100 -> 0 | W31: =H31/100 -> 1962335 | X31: =I31/100 -> 0 | Z31: =U31-W31 -> 1091101.2 | AA31: =V31-X31 -> 0
C32: 도서인쇄비 | F32: 249701176 | H32: 249444231 | U32: =F32/100 -> 2497011.8 | V32: =G32/100 -> 0 | W32: =H32/100 -> 2494442.3 | X32: =I32/100 -> 0 | Z32: =U32-W32 -> 2569.45 | AA32: =V32-X32 -> 0
C33: 임차료 | F33: 187335722 | H33: 133110533 | U33: =F33/100 -> 1873357.2 | V33: =G33/100 -> 0 | W33: =H33/100 -> 1331105.3 | X33: =I33/100 -> 0 | Z33: =U33-W33 -> 542251.89 | AA33: =V33-X33 -> 0
C34: 감가상각비 | F34: 4685107217 | H34: 6598800513 | U34: =F34/100 -> 46851072 | V34: =G34/100 -> 0 | W34: =H34/100 -> 65988005 | X34: =I34/100 -> 0 | Z34: =U34-W34 -> -19136933 | AA34: =V34-X34 -> 0
C35: 무형자산상각비 | F35: 1591150385 | H35: 2245900427 | U35: =F35/100 -> 15911504 | V35: =G35/100 -> 0 | W35: =H35/100 -> 22459004 | X35: =I35/100 -> 0 | Z35: =U35-W35 -> -6547500.4 | AA35: =V35-X35 -> 0
C36: 수선유지비 | F36: 560147885 | H36: 542802734 | U36: =F36/100 -> 5601478.8 | V36: =G36/100 -> 0 | W36: =H36/100 -> 5428027.3 | X36: =I36/100 -> 0 | Z36: =U36-W36 -> 173451.51 | AA36: =V36-X36 -> 0
C37: 차량유지비 | F37: 12421398 | H37: 16537350 | U37: =F37/100 -> 124213.98 | V37: =G37/100 -> 0 | W37: =H37/100 -> 165373.5 | X37: =I37/100 -> 0 | Z37: =U37-W37 -> -41159.52 | AA37: =V37-X37 -> 0
C38: 보험료 | F38: 12964679 | H38: 13347892 | U38: =F38/100 -> 129646.79 | V38: =G38/100 -> 0 | W38: =H38/100 -> 133478.92 | X38: =I38/100 -> 0 | Z38: =U38-W38 -> -3832.13 | AA38: =V38-X38 -> 0
C39: 지급수수료 | F39: 11661851506 | H39: 10146580085 | U39: =F39/100 -> 1.1661852e+08 | V39: =G39/100 -> 0 | W39: =H39/100 -> 1.014658e+08 | X39: =I39/100 -> 0 | Z39: =U39-W39 -> 15152714 | AA39: =V39-X39 -> 0
C40: 업무추진비 | F40: 173007037 | H40: 153125824 | U40: =F40/100 -> 1730070.4 | V40: =G40/100 -> 0 | W40: =H40/100 -> 1531258.2 | X40: =I40/100 -> 0 | Z40: =U40-W40 -> 198812.13 | AA40: =V40-X40 -> 0
C41: 광고선전비 | F41: 2416041343 | H41: 325365504 | U41: =F41/100 -> 24160413 | V41: =G41/100 -> 0 | W41: =H41/100 -> 3253655 | X41: =I41/100 -> 0 | Z41: =U41-W41 -> 20906758 | AA41: =V41-X41 -> 0
...

Sheet #3. 운영사업원가명세서
A1: 운 영 사 업 원 가 명 세 서
A2: 제 8 기 2024년 1월 1일부터 2024년 12월 31일까지
A3: 제 7 기 2023년 1월 1일부터 2023년 12월 31일까지
A5: 서울교통공사 | H5: (단위 : 원)
B6: 과 목 | E6: 제 8 기 | G6: 제 7 기
A7: Ⅰ. | B7: 인건비 | F7: 1339339597386 | H7: 1151418302421 | I7: =H7-F7 -> -187921294965 | L7: =E7/100 -> 0 | M7: =F7/100 -> 1.3393396e+10 | N7: =G7/100 -> 0 | O7: =H7/100 -> 1.1514183e+10 | Q7: =L7-N7 -> 0 | R7: =M7-O7 -> 1.8792129e+09
B8: 급여 | E8: 1128985933406 | G8: 1059469985632 | L8: =E8/100 -> 1.1289859e+10 | M8: =F8/100 -> 0 | N8: =G8/100 -> 1.05947e+10 | O8: =H8/100 -> 0 | Q8: =L8-N8 -> 6.9515948e+08 | R8: =M8-O8 -> 0
B9: 퇴직급여 | E9: 210353663980 | G9: 91948316789 | L9: =E9/100 -> 2.1035366e+09 | M9: =F9/100 -> 0 | N9: =G9/100 -> 9.1948317e+08 | O9: =H9/100 -> 0 | Q9: =L9-N9 -> 1.1840535e+09 | R9: =M9-O9 -> 0
A10: Ⅱ. | B10: 경비 | F10: 1350511904284 | H10: 1308753436529 | L10: =E10/100 -> 0 | M10: =F10/100 -> 1.3505119e+10 | N10: =G10/100 -> 0 | O10: =H10/100 -> 1.3087534e+10 | Q10: =L10-N10 -> 0 | R10: =M10-O10 -> 4.1758468e+08
B11: 복리후생비 | E11: 168192205387 | G11: 166252147644 | L11: =E11/100 -> 1.6819221e+09 | M11: =F11/100 -> 0 | N11: =G11/100 -> 1.6625215e+09 | O11: =H11/100 -> 0 | Q11: =L11-N11 -> 19400577 | R11: =M11-O11 -> 0
B12: 여비교통비 | E12: 591416117 | G12: 730818818 | L12: =E12/100 -> 5914161.2 | M12: =F12/100 -> 0 | N12: =G12/100 -> 7308188.2 | O12: =H12/100 -> 0 | Q12: =L12-N12 -> -1394027 | R12: =M12-O12 -> 0
B13: 수도광열비 | E13: 264169534539 | G13: 247053866681 | L13: =E13/100 -> 2.6416953e+09 | M13: =F13/100 -> 0 | N13: =G13/100 -> 2.4705387e+09 | O13: =H13/100 -> 0 | Q13: =L13-N13 -> 1.7115668e+08 | R13: =M13-O13 -> 0
B14: 공공요금및제세 | E14: 13899481677 | G14: 14395425045 | L14: =E14/100 -> 1.3899482e+08 | M14: =F14/100 -> 0 | N14: =G14/100 -> 1.4395425e+08 | O14: =H14/100 -> 0 | Q14: =L14-N14 -> -4959433.7 | R14: =M14-O14 -> 0
B15: 소모품비 | E15: 3859390106 | G15: 3991945879 | L15: =E15/100 -> 38593901 | M15: =F15/100 -> 0 | N15: =G15/100 -> 39919459 | O15: =H15/100 -> 0 | Q15: =L15-N15 -> -1325557.7 | R15: =M15-O15 -> 0
B16: 도서인쇄비 | E16: 884357785 | G16: 536195758 | L16: =E16/100 -> 8843577.8 | M16: =F16/100 -> 0 | N16: =G16/100 -> 5361957.6 | O16: =H16/100 -> 0 | Q16: =L16-N16 -> 3481620.3 | R16: =M16-O16 -> 0
B17: 임차료 | E17: 3761044542 | G17: 2988602113 | L17: =E17/100 -> 37610445 | M17: =F17/100 -> 0 | N17: =G17/100 -> 29886021 | O17: =H17/100 -> 0 | Q17: =L17-N17 -> 7724424.3 | R17: =M17-O17 -> 0
B18: 감가상각비 | E18: 407905262268 | G18: 396934908549 | L18: =E18/100 -> 4.0790526e+09 | M18: =F18/100 -> 0 | N18: =G18/100 -> 3.9693491e+09 | O18: =H18/100 -> 0 | Q18: =L18-N18 -> 1.0970354e+08 | R18: =M18-O18 -> 0
B19: 무형자산상각비 | E19: 3878191407 | G19: 3952048455 | L19: =E19/100 -> 38781914 | M19: =F19/100 -> 0 | N19: =G19/100 -> 39520485 | O19: =H19/100 -> 0 | Q19: =L19-N19 -> -738570.48 | R19: =M19-O19 -> 0
B20: 수선유지비 | E20: 55344351138 | G20: 82374892029 | L20: =E20/100 -> 5.5344351e+08 | M20: =F20/100 -> 0 | N20: =G20/100 -> 8.2374892e+08 | O20: =H20/100 -> 0 | Q20: =L20-N20 -> -2.7030541e+08 | R20: =M20-O20 -> 0
B21: 차량유지비 | E21: 311657922 | G21: 324476991 | L21: =E21/100 -> 3116579.2 | M21: =F21/100 -> 0 | N21: =G21/100 -> 3244769.9 | O21: =H21/100 -> 0 | Q21: =L21-N21 -> -128190.69 | R21: =M21-O21 -> 0
B22: 보험료 | E22: 1287353287 | G22: 1297750084 | L22: =E22/100 -> 12873533 | M22: =F22/100 -> 0 | N22: =G22/100 -> 12977501 | O22: =H22/100 -> 0 | Q22: =L22-N22 -> -103967.97 | R22: =M22-O22 -> 0
... B32: 잡비 | E32: 23663851150 | G32: 20806925106 | L32: =E32/100 -> 2.3663851e+08 | M32: =F32/100 -> 0 | N32: =G32/100 -> 2.0806925e+08 | O32: =H32/100 -> 0 | Q32: =L32-N32 -> 28569260 | R32: =M32-O32 -> 0
B33: 총계 | F33: 2689851501670 | H33: 2460171738950 | I33: =H33-F33 -> -229679762720 | L33: =E33/100 -> 0 | M33: =F33/100 -> 2.6898515e+10 | N33: =G33/100 -> 0 | O33: =H33/100 -> 2.4601717e+10 | Q33: =L33-N33 -> 0 | R33: =M33-O33 -> 2.2967976e+09

Sheet #4. 수탁사업원가명세서
A1: 수 탁 사 업 원 가 명 세 서
A2: 제 8 기 2024년 1월 1일부터 2024년 12월 31일까지
A3: 제 7 기 2023년 1월 1일부터 2023년 12월 31일까지
A5: 서울교통공사 | H5: (단위 : 원)
B6: 과 목 | E6: 제 8 기 | G6: 제 7 기
A7: Ⅰ. | B7: 인건비 | F7: 61291597869 | H7: 39612077686
B8: 급여 | E8: 55953770530 | G8: 36112407740
B9: 퇴직급여 | E9: 5337827339 | G9: 3499669946
A10: Ⅱ. | B10: 경비 | F10: 118796205391 | H10: 53671945172
B11: 복리후생비 | E11: 9915877299 | G11: 6795295451
B12: 여비교통비 | E12: 31810195 | G12: 17986497
B13: 수도광열비 | E13: 13419811576 | G13: 12021733866
B14: 공공요금및제세 | E14: 931311144 | G14: 696475553
B15: 소모품비 | E15: 3843697567 | G15: 693368874
B16: 도서인쇄비 | E16: 44656877 | G16: 32261702
B17: 임차료 | E17: 740617237 | G17: 510255562
B18: 감가상각비 | E18: 0 | G18: 0
B19: 무형자산상각비 | E19: 0 | G19: 0
B20: 수선유지비 | E20: 4800600711 | G20: 5726938672
B21: 차량유지비 | E21: 8597323 | G21: 5965391
B22: 보험료 | E22: 1302986873 | G22: 1377569025
... B34: 위탁수수료 | E34: 0 | G34: 0
B35: 총계 | F35: 180087803260 | H35: 93284022858
F39: =F35='#2. 손익계산서'!F19 -> TRUE | H39: =H35='#2. 손익계산서'!H19 -> TRUE

Sheet #5. 영업비용명세서
A1: 영 업 비 용 명 세 서
A2: 제 8 기 2024년 1월 1일부터 2024년 12월 31일까지
A3: 제 7 기 2023년 1월 1일부터 2023년 12월 31일까지
A5: 서울교통공사 | H5: (단위 : 원)
B6: 과 목 | E6: 제 8 기 | G6: 제 7 기
A7: Ⅰ. | B7: 인건비 | F7: 1420549084573 | H7: 1220240588196
B8: 급여 | E8: 1197926730963 | G8: 1122033002317
B9: 퇴직급여 | E9: 222622353610 | G9: 98207585879
A10: Ⅱ. | B10: 경비 | F10: 1593135247395 | H10: 1495687947904
B11: 복리후생비 | E11: 178034143475 | G11: 176335011617
B12: 여비교통비 | E12: 725082895 | G12: 822056692
B13: 수도광열비 | E13: 264438869745 | G13: 247327373050
B14: 공공요금및제세 | E14: 15882632975 | G14: 15824155815
B15: 소모품비 | E15: 4164733729 | G15: 4188179379
B16: 도서인쇄비 | E16: 1134058961 | G16: 785639989
B17: 임차료 | E17: 3948380264 | G17: 3121712646
B18: 감가상각비 | E18: 412590369485 | G18: 403533709062
B19: 무형자산상각비 | E19: 5469341792 | G19: 6197948882
B20: 수선유지비 | E20: 55904499023 | G20: 82917694763
B21: 차량유지비 | E21: 324079320 | G21: 341014341
B22: 보험료 | E22: 1300317966 | G22: 1311097976
... B34: 수탁사업원가 | E34: 180087803260 | G34: 93284022858
B35: 총계 | F35: 3013684331968 | H35: 2715928536100

Sheet #6. 자본변동표
A1: 자 본 변 동 표
A2: 제 8 기 : 2024년 1월 1일 부터 2024년 12월 31일까지
A3: 제 7 기 : 2023년 1월 1일 부터 2023년 12월 31일까지
A4: 서울교통공사 | E4: (단위 : 원)
A5: 과 목 | B5: 자 본 금 | C5: 기타포괄손익누계액 | D5: 이익잉여금 | E5: 총 계
A6: 2023.01.01(전기초) | B6: 23275822952094 | C6: 3270662709428 | D6: -17680766273939 | E6: 8865719387583
A7: 1. 현금출자 | B7: 554095949000 | C7: - | D7: - | E7: 554095949000
A8: 2. 공채이관 | B8: - | C8: - | D8: - | E8: -
A9: 3. 토지재평가이익 | B9: - | C9: -67138954347 | D9: - | E9: -67138954347
A10: 4. 매도가능증권평가이익 | B10: - | C10: 21409840 | D10: - | E10: 21409840
A11: 5. 지분법자본변동 | B11: - | C11: 304764 | D11: - | E11: 304764
A12: 6. 당기순이익(손실) | B12: - | C12: - | D12: -517287241679 | E12: -517287241679
A13: 2023.12.31(전기말) | B13: 23829918901094 | C13: 3203545469685 | D13: -18198053515618 | E13: 8835410855161
A14: 2024.01.01(당기초) | B14: 23829918901094 | C14: 3203545469685 | D14: -18198053515618 | E14: 8835410855161
A15: 1. 현금출자 | B15: 345331953000 | C15: - | D15: - | E15: 345331953000
A16: 2. 토지재평가이익 | B16: - | C16: -370897236 | D16: - | E16: -370897236
A17: 3. 매도가능증권평가이익 | B17: - | C17: 24428620 | D17: - | E17: 24428620
A18: 4. 지분법자본변동 | B18: - | C18: 111672 | D18: - | E18: 111672
A19: 5. 당기순이익(손실) | B19: - | C19: - | D19: -724126845664 | E19: -724126845664
A20: 2024.12.31(당기말) | B20: 24175250854094 | C20: 3203199112741 | D20: -18922180361282 | E20: 8456269605553

Sheet #7. 현금흐름표
A1: 현 금 흐 름 표
A2: 제 8 기 : 2024년 1월 1일 부터 2024년 12월 31일까지
A3: 제 7 기 : 2023년 1월 1일 부터 2023년 12월 31일까지
A4: 서울교통공사 | E4: (단위 : 원)
A5: 과 목 | B5: 제 8 기 | D5: 제 7 기
A6: Ⅰ. 영업활동으로인한현금흐름 | C6: -128273353745 | E6: -398645074385
A7: 1. 당기순손실 | B7: -724126845664 | D7: -517287241679
A8: 2. 현금의유출이없는비용등의가산 | B8: 662030475296 | D8: 529411838864
A9: 퇴직급여 | B9: 227960180949 | D9: 101707255825
A10: 감가상각비 | B10: 412590369485 | D10: 403533709062
A11: 기타비유동자산처분손실 | B11: 9581798 | D11: -
A12: 유형자산처분손실 | B12: - | D12: 8157119177
A13: 무형자산상각비 | B13: 5469341792 | D13: 6197948882
A14: 대손상각비 | B14: 4274589285 | D14: 1986796846
A15: 재고자산폐기손실 | B15: 906076787 | D15: 89937432
A16: 유형자산폐기손실 | B16: 10069617539 | D16: 5338018664
A17: 무형자산폐기손실 | B17: 3577948 | D17: 29613333
A18: 기타의대손상각비 | B18: 747139713 | D18: 982475148
A19: 잡손실 | B19: - | D19: 1057500000
A20: 지분법손실 | B20: - | D20: 331464495
A21: 3. 현금의유입이없는수익등의차감 | B21: -47319112194 | D21: -117805299875
A22: 기타비유동자산처분이익 | B22: 5491625092 | D22: 1544181876
A23: 유형자산처분이익 | B23: 1119751101 | D23: 50265264613
A24: 자산수증이익 | B24: 10046499678 | D24: 55284291842
A25: 지분법평가이익 | B25: 30573449261 | D25: 10704093214
A26: 잡이익 | B26: 31708690 | D26: 7468330
A27: 기타사업수익 | B27: 2295875 | D27: -
A28: 채무면제이익 | B28: 53782497 | D28: -
A29: 4. 영업활동으로인한자산부채의변동 | B29: -18857871183 | D29: -292964371695
A30: 매출채권의 증가(감소) | B30: -49115186579 | D30: -25755998444
A31: 미수금의 증가(감소) | B31: -6307616002 | D31: 5646901288
A32: 미수수익의 증가(감소) | B32: -365787249 | D32: 852142815
A33: 선급금의 증가(감소) | B33: -407014733 | D33: 1027796290
A34: 선급비용의 증가(감소) | B34: 506064501 | D34: -123242971
A35: 당기법인세자산의 증가(감소) | B35: -618379225 | D35: -937468320
A36: 기타의당좌자산의 증가(감소) | B36: - | D36: 22141400
A37: 재고자산의 증가(감소) | B37: -3261726913 | D37: -11549163268
A38: 미지급금의 증가(감소) | B38: 25370705338 | D38: -76362908435
A39: 선수금의 증가(감소) | B39: -1334915670 | D39: 2454283799
A40: 예수금의 증가(감소) | B40: 41210976907 | D40: 3444652677
...

Sheet #8. 합계잔액시산표.
A1: 합 계 잔 액 시 산 표
A2: 서울교통공사 | E2: (단위:원)
A3: 잔액 | B3: 차변 | C3: 계정과목 | D3: 대변 | E3: 잔액 | F3: 차이 | G3: 검증 | H3: 비고 | I3: 잔액
A4: 3174935820 | B4: 365229301537 | C4: 현금 | D4: 362054365717 | E4: 0 | F4: =B4-D4 -> 3174935820 | G4: =F4=I4 -> TRUE | H4: 재무상태표(차변) | I4: =A4-E4 -> 3174935820
A5: 0 | B5: 377118369851 | C5: 당좌예금 | D5: 377118369851 | E5: 0 | F5: =B5-D5 -> 0 | G5: =F5=I5 -> TRUE | H5: 재무상태표(차변) | I5: =A5-E5 -> 0
A6: 9622368361 | B6: 19000362671535 | C6: 보통예금 | D6: 18990740303174 | E6: 0 | F6: =B6-D6 -> 9622368361 | G6: =F6=I6 -> TRUE | H6: 재무상태표(차변) | I6: =A6-E6 -> 9622368361
A7: 492627363412 | B7: 5700547593330 | C7: 현금성자산 | D7: 5207920229918 | E7: 0 | F7: =B7-D7 -> 492627363412 | G7: =F7=I7 -> TRUE | H7: 재무상태표(차변) | I7: =A7-E7 -> 492627363412
A8: 0 | B8: 165593590034 | C8: 국고보조금 | D8: 251492455018 | E8: 85898864984 | F8: =B8-D8 -> -85898864984 | G8: =F8=I8 -> TRUE | H8: 재무상태표(차변) | I8: =A8-E8 -> -85898864984
A9: 0 | B9: 392101933 | C9: 지방자치단체보조금 | D9: 2839124818 | E9: 2447022885 | F9: =B9-D9 -> -2447022885 | G9: =F9=I9 -> TRUE | H9: 재무상태표(차변) | I9: =A9-E9 -> -2447022885
A10: 0 | B10: 11043462440 | C10: 수탁자산취득보조금 | D10: 20387613734 | E10: 9344151294 | F10: =B10-D10 -> -9344151294 | G10: =F10=I10 -> TRUE | H10: 재무상태표(차변) | I10: =A10-E10 -> -9344151294
A11: 1341011674 | B11: 1364486594 | C11: 단기대여금 | D11: 23474920 | E11: 0 | F11: =B11-D11 -> 1341011674 | G11: =F11=I11 -> TRUE | H11: 재무상태표(차변) | I11: =A11-E11 -> 1341011674
A12: 162944444705 | B12: 2648389076434 | C12: 외상매출금 | D12: 2485444631729 | E12: 0 | F12: =B12-D12 -> 162944444705 | G12: =F12=I12 -> TRUE | H12: 재무상태표(차변) | I12: =A12-E12 -> 162944444705
A13: 0 | B13: 14097368143 | C13: 대손충당금 | D13: 42823779700 | E13: 28726411557 | F13: =B13-D13 -> -28726411557 | G13: =F13=I13 -> TRUE | H13: 재무상태표(차변) | I13: =A13-E13 -> -28726411557
A14: 43218431794 | B14: 174642484648 | C14: 미수금 | D14: 131424052854 | E14: 0 | F14: =B14-D14 -> 43218431794 | G14: =F14=I14 -> TRUE | H14: 재무상태표(차변) | I14: =A14-E14 -> 43218431794
A15: 0 | B15: 165044063 | C15: 대손충당금 | D15: 34997074599 | E15: 34832030536 | F15: =B15-D15 -> -34832030536 | G15: =F15=I15 -> TRUE | H15: 재무상태표(차변) | I15: =A15-E15 -> -34832030536
... A70: 0 | B70: 0 | C70: 감가상각누계액 | D70: 7284269783 | E70: 7284269783 | F70: =B70-D70 -> -7284269783 | G70: =F70=I70 -> TRUE | H70: 재무상태표(차변) | I70: =A70-E70 -> -7284269783
C71: 기계장치수탁자산 | F71: =B71-D71 -> 0 | G71: =F71=I71 -> TRUE | H71: 재무상태표(차변) | I71: =A71-E71 -> 0
C72: 기계장치수탁자산취득보조금 | F72: =B72-D72 -> 0 | G72: =F72=I72 -> TRUE | H72: 재무상태표(차변) | I72: =A72-E72 -> 0
C73: 기계장치수탁자산감가상각누계액 | F73: =B73-D73 -> 0 | G73: =F73=I73 -> TRUE | H73: 재무상태표(차변) | I73: =A73-E73 -> 0
C74: 선로설비수탁자산 | F74: =B74-D74 -> 0 | G74: =F74=I74 -> TRUE | H74: 재무상태표(차변) | I74: =A74-E74 -> 0
C75: 선로설비수탁자산취득보조금 | F75: =B75-D75 -> 0 | G75: =F75=I75 -> TRUE | H75: 재무상태표(차변) | I75: =A75-E75 -> 0
C76: 선로설비수탁자산감가상각누계액 | F76: =B76-D76 -> 0 | G76: =F76=I76 -> TRUE | H76: 재무상태표(차변) | I76: =A76-E76 -> 0
C77: 선로설비수탁자산국고보조금 | F77: =B77-D77 -> 0 | G77: =F77=I77 -> TRUE | H77: 재무상태표(차변) | I77: =A77-E77 -> 0
C78: 전로설비수탁자산 | F78: =B78-D78 -> 0 | G78: =F78=I78 -> TRUE | H78: 재무상태표(차변) | I78: =A78-E78 -> 0
C79: 전로설비수탁자산취득보조금 | F79: =B79-D79 -> 0 | G79: =F79=I79 -> TRUE | H79: 재무상태표(차변) | I79: =A79-E79 -> 0
C80: 전로설비수탁자산감가상각누계액 | F80: =B80-D80 -> 0 | G80: =F80=I80 -> TRUE | H80: 재무상태표(차변) | I80: =A80-E80 -> 0
C81: 전로설비수탁자산국고보조금 | F81: =B81-D81 -> 0 | G81: =F81=I81 -> TRUE | H81: 재무상태표(차변) | I81: =A81-E81 -> 0
C82: 전동차량수탁자산 | F82: =B82-D82 -> 0 | G82: =F82=I82 -> TRUE | H82: 재무상태표(차변) | I82: =A82-E82 -> 0
... C94: 건설중수탁자산취득보조금 | F94: =B94-D94 -> 0 | G94: =F94=I94 -> TRUE | H94: 재무상태표(차변) | I94: =A94-E94 -> 0
A95: 50463912 | B95: 732207668 | C95: 특허권 | D95: 681743756 | E95: 0 | F95: =B95-D95 -> 50463912 | G95: =F95=I95 -> TRUE | H95: 재무상태표(차변) | I95: =A95-E95 -> 50463912
A96: 16000 | B96: 46081962 | C96: 실용신안권 | D96: 46065962 | E96: 0 | F96: =B96-D96 -> 16000 | G96: =F96=I96 -> TRUE | H96: 재무상태표(차변) | I96: =A96-E96 -> 16000
A97: 830903 | B97: 12141200 | C97: 의장권 | D97: 11310297 | E97: 0 | F97: =B97-D97 -> 830903 | G97: =F97=I97 -> TRUE | H97: 재무상태표(차변) | I97: =A97-E97 -> 830903
A98: 3154634 | B98: 146797067 | C98: 상표권 | D98: 143642433 | E98: 0 | F98: =B98-D98 -> 3154634 | G98: =F98=I98 -> TRUE | H98: 재무상태표(차변) | I98: =A98-E98 -> 3154634
A99: 99600438211 | B99: 99600438211 | C99: 차지권 | D99: 0 | E99: 0 | F99: =B99-D99 -> 99600438211 | G99: =F99=I99 -> TRUE | H99: 재무상태표(차변) | I99: =A99-E99 -> 99600438211
A100: 9851553414 | B100: 17438764993 | C100: 소프트웨어 | D100: 7587211579 | E100: 0 | F100: =B100-D100 -> 9851553414 | G100: =F100=I100 -> TRUE | H100: 재무상태표(차변) | I100: =A100-E100 -> 9851553414
A101: 0 | B101: 0 | C101: 국고보조금 | D101: 1354319346 | E101: 1354319346 | F101: =B101-D101 -> -1354319346 | G101: =F101=I101 -> TRUE | H101: 재무상태표(차변) | I101: =A101-E101 -> -1354319346
A102: 762877054 | B102: 762877054 | C102: 국고/감가상각누계액 | D102: 0 | E102: 0 | F102: =B102-D102 -> 762877054 | G102: =F102=I102 -> TRUE | H102: 재무상태표(차변) | I102: =A102-E102 -> 762877054
A103: 1095416912 | B103: 1095416912 | C103: 수탁자산소프트웨어 | D103: 0 | E103: 0 | F103: =B103-D103 -> 1095416912 | G103: =F103=I103 -> TRUE | H103: 재무상태표(차변) | I103: =A103-E103 -> 1095416912
A104: 0 | B104: 33390221 | C104: 수탁자산소프트웨어취득보조금 | D104: 76054115 | E104: 42663894 | F104: =B104-D104 -> -42663894 | G104: =F104=I104 -> TRUE | H104: 재무상태표(차변) | I104: =A104-E104 -> -42663894
A105: 0 | B105: 0 | C105: 수탁자산소프트웨어감가상각누계액 | D105: 1052753018 | E105: 1052753018 | F105: =B105-D105 -> -1052753018 | G105: =F105=I105 -> TRUE | H105: 재무상태표(차변) | I105: =A105-E105 -> -1052753018
...
