Workbook

Sheet 재무상태표
B1: 1. 재 무 상 태 표
B2: 제29기 2009년 12월 31일 현재
B3: 제28기 2008년 12월 31일 현재
B4: 서울메트로 | J4: (단위 : 원)
C5: 과 목 | G5: 제29(당)기 | I5: 제28(전)기
B6: 자 산
B7: Ⅰ. | C7: 유동자산 | H7: 269091345182 | J7: 521840942319
B8: (1) | D8: 당좌자산 | H8: 228490338749 | J8: 477280020536
A9: 1 | C9: 1. | E9: 현금및현금성자산 | G9: 108162981264 | I9: 91120389836
A10: 3 | C10: 2. | E10: 단기투자자산 | G10: 70384600136 | I10: 304310822964
A11: 4 | C11: 3. | E11: 매출채권 | G11: 12119215868 | I11: 64008879377
A12: 5 | E12: (대손충당금) | G12: -266537211 | I12: -266537211
A13: 6 | C13: 4. | E13: 단기대여금 | G13: 1896762770 | I13: 550982870
A14: 7 | C14: 5. | E14: 미수금 | G14: 4353947168 | I14: 3161115900
A15: 8 | E15: (대손충당금) | G15: -85129505 | I15: -85129505
A16: 102 | C16: 6 | E16: 미수수익 | G16: 745416032 | I16: 7725053492
A17: 9 | C17: 7 | E17: 선급금 | G17: 27629556333 | I17: 708600000
A18: 10 | C18: 8 | E18: 선급비용 | G18: 472064574 | I18: 476335733
A19: 11 | C19: 9 | E19: 예치금 | G19: 389706160 | I19: 135522000
A20: 13 | C20: 10 | E20: 당기법인세자산 | G20: 2687755160 | I20: 5433985080
B21: (2) | D21: 재고자산 | H21: 40601006433 | J21: 44560921783
A22: 15 | C22: 1. | E22: 저장품 | G22: 39939245447 | I22: 34544650463
A23: 16 | C23: 2. | E23: 미착품 | G23: 661760986 | I23: 10016271320
B24: Ⅱ. | C24: 비유동자산 | H24: 3878150006247 | J24: 3420551063640
B25: (1) | D25: 투자자산 | H25: 48354914577 | J25: 38680997415
A26: 103 | C26: 1. | E26: 장기대여금 | G26: 46954914577 | I26: 38680997415
A27: 17 | C27: 2. | E27: 지분법적용투자주식 | G27: 1400000000 | I27: -
B28: (2) | D28: 유형자산 | H28: 3788191547385 | J28: 3356250257194
A29: 19 | C29: 1. | E29: 토지 | G29: 137127108912 | I29: 137186503755
A30: 20 | C30: 2. | E30: 건물 | G30: 231837332385 | I30: 210578923091
A31: 21 | E31: (감가상각누계액) | G31: -104281098140 | I31: -95538862321
A32: 23 | C32: 3. | E32: 기계장치 | G32: 50792110467 | I32: 50975506062
A33: 24 | E33: (감가상각누계액) | G33: -19842129660 | I33: -18825406197
A34: 25 | C34: 4. | E34: 선로설비 | G34: 2963525404942 | I34: 2907290273663
A35: 26 | E35: (감가상각누계액) | G35: -981389724117 | I35: -909761817251
A36: 28 | C36: 5. | E36: 전로설비 | G36: 842047506119 | I36: 727986406681
A37: 29 | E37: (감가상각누계액) | G37: -316032749086 | I37: -358924897553
A38: 31 | C38: 6. | E38: 전동차량 | G38: 1548682534579 | I38: 1394688245605
A39: 32 | E39: (감가상각누계액) | G39: -721652747116 | I39: -815020934707
A40: 33 | C40: 7. | E40: 자동차운반구 | G40: 2389731847 | I40: 2437026268
...

Sheet 손익계산서
B1: 2. 손 익 계 산 서
B2: 제29기 2009년 1월1일부터 12월 31일까지
B3: 제28기 2008년 1월1일부터 12월 31일까지
B4: 서울메트로 | J4: (단위 : 원)
B5: 과 목 | G5: =재무상태표!G5 -> 제29(당)기 | I5: 제28(전)기
B6: Ⅰ. | C6: 매출액 | H6: =SUM(G7:G9) -> 898868026584 | J6: =SUM(I7:I9) -> 935011324657
B7: 1. | D7: 운수사업수익 | G7: 783888133813 | I7: 790898672136
A8: 1 | B8: 2. | D8: 부대사업수익 | G8: 80441762906 | I8: 101609759879
A9: 2 | B9: 3. | D9: 기타사업수익 | G9: 34538129865 | I9: 42502892642
B10: Ⅱ. | C10: 매출원가 | H10: =SUM(G11:G11) -> 1028365658702 | J10: =SUM(I11:I11) -> 1023651511411
A11: 4 | B11: 1. | D11: 운영사업원가 | G11: 1028365658702 | I11: 1023651511411
B12: Ⅲ. | C12: 매출총이익 | H12: =H6-H10 -> -129497632118 | J12: =J6-J10 -> -88640186754
B13: Ⅳ. | C13: 판매비와관리비 | H13: =SUM(G14:G38) -> 65275640196 | J13: =SUM(I14:I38) -> 57667080874
A14: 5 | B14: 1. | D14: 급여 | G14: 34940940197 | I14: 30805466949
A15: 6 | B15: 2. | D15: 퇴직급여 | G15: 4824880100 | I15: 3495317710
A16: 7 | B16: 3. | D16: 복리후생비 | G16: 5123892328 | I16: 4787550157
A17: 8 | B17: 4. | D17: 여비교통비 | G17: 204457510 | I17: 93391761
A18: 9 | B18: 5. | D18: 통신비 | G18: 132838660 | I18: 178631502
A19: 10 | B19: 6. | D19: 수도광열비 | G19: 133686210 | I19: 194599271
A20: 11 | B20: 7. | D20: 세금과공과 | G20: 86504460 | I20: 65193560
A21: 12 | B21: 8. | D21: 소모품비 | G21: 303745888 | I21: 276004107
A22: 13 | B22: 9. | D22: 도서인쇄비 | G22: 417217815 | I22: 421323720
A23: 14 | B23: 10. | D23: 지급임차료 | G23: 71363760 | I23: 61820472
A24: 15 | B24: 11. | D24: 감가상각비 | G24: 4151453495 | I24: 4056737520
A25: 16 | B25: 12. | D25: 무형자산상각비 | G25: 2557265221 | I25: 2151208958
... A38: 31 | B38: 25. | D38: 잡비 | G38: 1172628186 | I38: 913640363
B39: Ⅴ. | C39: 영업손익 | H39: =H12-H13 -> -194773272314 | J39: =J12-J13 -> -146307267628
B40: Ⅵ. | C40: 영업외수익 | H40: =SUM(G41:G50) -> 25308170574 | J40: =SUM(I41:I50) -> 58705472975
A41: 33 | B41: 1. | D41: 이자수익 | G41: 12265151558 | I41: 35363931753
A42: 34 | B42: 2. | D42: 외환차익 | G42: 11298281 | I42: -
A43: 35 | B43: 3. | D43: 임대료 | G43: 184314655 | I43: 359431872
A44: 36 | B44: 4. | D44: 폐품매각수익 | G44: 3950205462 | I44: 1002459303
A45: 37 | B45: 5. | D45: 수입위약배상금 | G45: 1867877493 | I45: 4343549217
B46: 6. | D46: 유형자산처분이익 | G46: 51524407 | I46: -
A47: 40 | B47: 7. | D47: 자산수증이익 | G47: 3940299 | I47: 2741092964
A48: 41 | B48: 8. | D48: 공채상환이익 | G48: 1449686754 | I48: 1454722114
A49: 42 | B49: 9. | D49: 전기오류수정이익 | G49: - | I49: 890175984
A50: 43 | B50: 10. | D50: 잡이익 | G50: 5524171665 | I50: 12550109768
B51: Ⅶ. | C51: 영업외비용 | H51: =SUM(G52:G62) -> 67918571837 | J51: =SUM(I52:I62) -> 56253084724
A52: 44 | B52: 1. | D52: 이자비용 | G52: 49880326038 | I52: 48790515123
...

Sheet 운영사업원가명세서
B1: ( 운 영 사 업 원 가 명 세 서 )
B2: =손익계산서!B2 -> 제29기 2009년 1월1일부터 12월 31일까지
B3: =손익계산서!B3 -> 제28기 2008년 1월1일부터 12월 31일까지
B4: 서울메트로 | F4: (단위 : 원)
B5: 과 목 | E5: =재무상태표!G5 -> 제29(당)기 | F5: =손익계산서!I5 -> 제28(전)기
A6: 1 | B6: 1. | C6: 급여 | E6: 491751913327 | F6: 492486450458
A7: 2 | B7: 2. | C7: 퇴직급여 | E7: 62718803876 | F7: 101393672645
A8: 3 | B8: 3. | C8: 복리후생비 | E8: 66710417315 | F8: 64027247996
A9: 4 | B9: 4. | C9: 여비교통비 | E9: 673296504 | F9: 495527981
A10: 5 | B10: 5. | C10: 통신비 | E10: 387329207 | F10: 296486619
A11: 6 | B11: 6. | C11: 수도광열비 | E11: 66574108114 | F11: 64204404751
A12: 7 | B12: 7. | C12: 세금과공과 | E12: 607380142 | F12: 597233570
A13: 8 | B13: 8. | C13: 소모품비 | E13: 2494595513 | F13: 2032985151
A14: 10 | B14: 9. | C14: 피복비 | E14: 1717170013 | F14: 2602128128
A15: 11 | B15: 10. | C15: 도서인쇄비 | E15: 962667867 | F15: 1152700510
A16: 12 | B16: 11. | C16: 임차료 | E16: 300537583 | F16: 281496986
A17: 13 | B17: 12. | C17: 감가상각비 | E17: 169597106806 | F17: 147662014697
... A23: 19 | B23: 18. | C23: 운반및보관료 | E23: 29589753 | F23: 49968600
B24: 19. | C24: 업무추진비 | E24: 50000 | F24: 643000
A25: 20 | B25: 20. | C25: 광고선전비 | E25: 160188603 | F25: 251769980
A26: 21 | B26: 21. | C26: 교육훈련비 | E26: 3750278672 | F26: 6160980620
A27: 22 | B27: 22. | C27: 포상비 | E27: 418611154 | F27: 314056410
A28: 24 | B28: 23. | C28: 협회비 | E28: 19303118 | F28: 15006500
A29: 25 | B29: 24. | C29: 피해보상비 | E29: 46589058 | F29: 74132350
A30: 26 | B30: 25. | C30: 경상연구비 | E30: 4189817600 | F30: 3328821290
A31: 27 | B31: 26. | C31: 재료비기타 | E31: 19261375840 | F31: 21587616118
A32: 28 | B32: 27. | C32: 재고자산평가손실 | E32: 136628168 | F32: 324559221
A33: 30 | B33: 28. | C33: 잡비 | E33: 1718361033 | F33: 1516067609
B34: 합계 | E34: =SUM(E6:E33) -> 1028365658702 | F34: =SUM(F6:F33) -> 1023651511411

Sheet 현금흐름표
A1: 3. 현 금 흐 름 표
A2: 제29기 2009년1월1일부터 2009년12월31일까지
A3: 제28기 2008년1월1일부터 2008년12월31일까지
A4: 서울메트로 | G4: (단위:원)
A5: 과목 | D5: 제29(당)기 | F5: 제28(전)기
A6: Ⅰ.영업활동으로인한현금흐름 | E6: -54894062225 | G6: 7478317681
B7: 1.당기순손실 | D7: -237383673577 | F7: -143854889377
B8: 2.현금의유출이없는비용등의가산 | D8: 261167460652 | F8: 262994688026
C9: 가. 퇴직급여 | D9: 67543683976 | F9: 104888990355
C10: 나. 감가상각비 | D10: 173748560301 | F10: 151718752217
C11: 다. 무형자산상각비 | D11: 3122952061 | F11: 2727607297
C12: 라. 이자비용(할인차금상각) | D12: 3083892 | F12: 5470187
C13: 마. 재고자산평가손실 | D13: 136628168 | F13: 324559221
C14: 바. 재고자산폐기손실 | D14: 115908298 | F14: -
C15: 사. 재고자산감모손실 | D15: - | F15: 43373546
C16: 아. 유형자산처분손실 | D16: 43488250 | F16: -
C17: 자. 유형자산폐기손실 | D17: 4943733559 | F17: 1374785864
C18: 차. 유형자산손상차손 | D18: 11507356292 | F18: 1057052998
C19: 카. 무형자산손상차손 | D19: 2065855 | F19: 197165
C20: 타. 전기오류수정손실 | D20: - | F20: 853899176
B21: 3.현금의유입이없는수익등의차감 | D21: -5455356922 | F21: -6088450365
C22: 가. 유형자산처분이익 | D22: 51524407 | F22: -
C23: 나. 자산수증이익 | D23: 3940299 | F23: -2741092964
C24: 다. 폐품매각수익 | D24: 3950205462 | F24: -1002459303
C25: 라. 공채상환이익 | D25: 1449686754 | F25: -1454722114
C26: 마. 전기오류수정이익 | D26: - | F26: -890175984
B27: 4.영업활동으로인한자산부채의변동 | D27: -73222492378 | F27: -105573030603
C28: 가. 매출채권의 감소(증가) | D28: 51889663509 | F28: -10156984326
C29: 나. 미수금의 증가 | D29: -1192831268 | F29: -1736398011
C30: 다. 미수수익의 감소 | D30: 6979637460 | F30: 3459320835
C31: 라. 선급금의 증가 | D31: -26920956333 | F31: -27099145861
C32: 마. 선급비용의 감소(증가) | D32: 4271159 | F32: -70926300
C33: 바. 부가세대급금의 감소(증가) | D33: -12810000 | F33: 1165500
C34: 사. 선급법인세의 감소(증가) | D34: 2746229920 | F34: -2197747960
C35: 아. 저장품의 감소(증가) | D35: -4826815504 | F35: 3757502049
C36: 자. 미착품의 감소(증가) | D36: 9354510334 | F36: -356721642
C37: 차. 미지급금의 증가(감소) | D37: -6263675647 | F37: 11452778281
C38: 카. 선수금의 감소 | D38: -811632057 | F38: -190524079
C39: 타. 예수금의 증가(감소) | D39: -22847395127 | F39: 11580845263
... C46: 머. 국민연금전환금의 감소 | D46: 70705500 | F46: 46804600
...

Sheet 자본변동표
A1: 4. 자 본 변 동 표
A2: =손익계산서!B2 -> 제29기 2009년 1월1일부터 12월 31일까지
A3: =손익계산서!B3 -> 제28기 2008년 1월1일부터 12월 31일까지
A5: 서울메트로 | D5: (단위 : 원)
A6: 과 목 | B6: 자본금 | C6: 이익잉여금 | D6: 총 계
A7: 2009.01.01(보고금액) | B7: 6332158676711 | C7: 5413669196854 | D7: 918489479857
A8: 1. 당기순손실 | B8: - | C8: 143854889377 | D8: 143854889377
A9: 2. 유상증자 | B9: 381991638218 | C9: - | D9: 318991638218
A10: 2009.12.31 | B10: 6714150314929 | C10: 5557524086231 | D10: 1156626228698
A11: 2010.01.01(보고금액) | B11: 6714150314929 | C11: 5557524086231 | D11: 1156626228698
A12: 1. 당기순손실 | B12: - | C12: 237383673577 | D12: 237383673577
A13: 2. 유상증자 | B13: 517935089690 | C13: - | D13: 517935089690
A14: 2010.12.31 | B14: 7232085404619 | C14: 5794907759808 | D14: 1437177644811
