Workbook
Name DATA1: #REF!
Name DATA1: #REF!
Name DATA10: #REF!
Name DATA10: #REF!
Name DATA11: #REF!
Name DATA11: #REF!
Name DATA12: #REF!
Name DATA12: #REF!
Name DATA13: #REF!
Name DATA13: #REF!
Name DATA14: #REF!
Name DATA14: #REF!
Name DATA15: #REF!
Name DATA15: #REF!
Name DATA16: #REF!
Name DATA16: #REF!
Name DATA17: #REF!
Name DATA17: #REF!
Name DATA18: #REF!
Name DATA18: #REF!
Name DATA19: #REF!
Name DATA19: #REF!
Name DATA2: #REF!
Name DATA2: #REF!
Name DATA20: #REF!
Name DATA20: #REF!
Name DATA21: #REF!
Name DATA21: #REF!
Name DATA22: #REF!
Name DATA22: #REF!
Name DATA23: #REF!
Name DATA23: #REF!
Name DATA24: #REF!
Name DATA24: #REF!
Name DATA25: #REF!
Name DATA25: #REF!
Name DATA26: #REF!
Name DATA26: #REF!
Name DATA27: #REF!
Name DATA27: #REF!
Name DATA28: #REF!
Name DATA28: #REF!
Name DATA29: #REF!
Name DATA29: #REF!
Name DATA3: #REF!
Name DATA3: #REF!
Name DATA30: #REF!
Name DATA30: #REF!
Name DATA31: #REF!
Name DATA31: #REF!
Name DATA32: #REF!
Name DATA32: #REF!
Name DATA33: #REF!
Name DATA33: #REF!
Name DATA34: #REF!
Name DATA34: #REF!
Name DATA35: #REF!
Name DATA35: #REF!
Name DATA36: #REF!
Name DATA36: #REF!

Sheet #1. 재무상태표
A1: 재 무 상 태 표
A2: 제 3 기 2019년 12월 31일 현재
A3: 제 2 기 2018년 12월 31일 현재
A5: 서울교통공사 | I5: (단위 : 원)
B6: 과 목 | F6: 제 3 기 (2019.12.31.) | H6: 제 2 기 (2018.12.31.)
A7: 자 산
A8: Ⅰ. | B8: 유동자산 | G8: 239730101469 | I8: 284647550472 | K8: =G8-I8 -> -44917449003
A9: (1) | C9: 당좌자산 | G9: 181346406187 | I9: 223283156931 | K9: =G9-I9 -> -41936750744
D10: 현금및현금성자산 | F10: 192557051013 | H10: 273060463855 | J10: =F10-H10 -> -80503412842 | K10: =G10-I10 -> 0
D11: (정부보조금) | F11: -100004857444 | H11: -142997365290 | J11: =F11-H11 -> 42992507846 | K11: =G11-I11 -> 0
D12: (수탁자산취득보조금) | F12: -3503880613 | H12: -2492242124 | J12: =F12-H12 -> -1011638489 | K12: =G12-I12 -> 0
D13: 단기금융상품 | F13: 0 | H13: 0 | J13: =F13-H13 -> 0 | K13: =G13-I13 -> 0
D14: 단기대여금 | F14: 1915569210 | H14: 2570654530 | J14: =F14-H14 -> -655085320 | K14: =G14-I14 -> 0
D15: 매출채권 | F15: 76086314824 | H15: 81309546847 | J15: =F15-H15 -> -5223232023 | K15: =G15-I15 -> 0
D16: (대손충당금) | F16: -13784148963 | H16: -8542621888 | J16: =F16-H16 -> -5241527075 | K16: =G16-I16 -> 0
D17: 미수금 | F17: 36074228163 | H17: 23954003991 | J17: =F17-H17 -> 12120224172 | K17: =G17-I17 -> 0
D18: (대손충당금) | F18: -22791370223 | H18: -14750678043 | J18: =F18-H18 -> -8040692180 | K18: =G18-I18 -> 0
D19: 미수수익 | F19: 445733 | H19: 0 | J19: =F19-H19 -> 445733 | K19: =G19-I19 -> 0
D20: 선급금 | F20: 12527262561 | H20: 7539873308 | J20: =F20-H20 -> 4987389253 | K20: =G20-I20 -> 0
D21: 선급비용 | F21: 313300187 | H21: 364106636 | J21: =F21-H21 -> -50806449 | K21: =G21-I21 -> 0
... D24: 기타의당좌자산 | F24: 1468617124 | H24: 2284340138 | J24: =F24-H24 -> -815723014 | K24: =G24-I24 -> 0
A25: (2) | C25: 재고자산 | G25: 58383695282 | I25: 61364393541 | J25: =F25-H25 -> 0 | K25: =G25-I25 -> -2980698259
D26: 저장품 | F26: 52989011274 | H26: 58047077787 | J26: =F26-H26 -> -5058066513 | K26: =G26-I26 -> 0
D27: 미착품 | F27: 5394684008 | H27: 3317315754 | J27: =F27-H27 -> 2077368254 | K27: =G27-I27 -> 0
A28: Ⅱ. | B28: 비유동자산 | G28: 12959314696015 | I28: 12957776348902 | J28: =F28-H28 -> 0 | K28: =G28-I28 -> 1538347113
A29: (1) | C29: 투자자산 | G29: 75689454308 | I29: 80678527852 | J29: =F29-H29 -> 0 | K29: =G29-I29 -> -4989073544
D30: 매도가능증권 | F30: 400737620 | H30: 380543600 | J30: =F30-H30 -> 20194020 | K30: =G30-I30 -> 0
D31: 장기대여금 | F31: 55961110540 | H31: 60660597552 | J31: =F31-H31 -> -4699487012 | K31: =G31-I31 -> 0
D32: 지분법적용투자주식 | F32: 19327606148 | H32: 19637386700 | J32: =F32-H32 -> -309780552 | K32: =G32-I32 -> 0
C33: 4. | D33: 장기금융상품 | H33: 0 | J33: =F33-H33 -> 0 | K33: =G33-I33 -> 0
A34: (2) | C34: 유형자산 | G34: 12762232922256 | I34: 12756029961391 | J34: =F34-H34 -> 0 | K34: =G34-I34 -> 6202960865
D35: 토지 | F35: 3520085114300 | H35: 3519712053700 | J35: =F35-H35 -> 373060600 | K35: =G35-I35 -> 0
D36: 건물 | F36: 452542702541 | H36: 447268641121 | J36: =F36-H36 -> 5274061420 | K36: =G36-I36 -> 0
D37: (감가상각누계액) | F37: -298642117567 | H37: -288446731771 | J37: =F37-H37 -> -10195385796 | K37: =G37-I37 -> 0
D38: (정부보조금) | F38: -523762764 | H38: -250968614 | J38: =F38-H38 -> -272794150 | K38: =G38-I38 -> 0
D39: 기계장치 | F39: 92695433375 | H39: 93422667399 | J39: =F39-H39 -> -727234024 | K39: =G39-I39 -> 0
D40: (감가상각누계액) | F40: -56525316138 | H40: -55264387274 | J40: =F40-H40 -> -1260928864 | K40: =G40-I40 -> 0
D41: 선로설비 | F41: 11707905628584 | H41: 11554316074955 | J41: =F41-H41 -> 153589553629 | K41: =G41-I41 -> 0
D42: (감가상각누계액) | F42: -4504510544079 | H42: -4275713382177 | J42: =F42-H42 -> -228797161902 | K42: =G42-I42 -> 0
D43: (정부보조금) | F43: -65101252823 | H43: -46020024221 | J43: =F43-H43 -> -19081228602 | K43: =G43-I43 -> 0
...

Sheet #2. 손익계산서
A1: 손 익 계 산 서
A2: 제 3 기 2019년 1월 1일부터 2019년 12월 31일까지
A3: 제 2 기 2018년 1월 1일부터 2018년 12월 31일까지
A5: 서울교통공사 | I5: (단위 : 원)
B6: 과 목 | F6: 제 3 기 | H6: 제 2 기
A7: Ⅰ. | B7: 매출액 | G7: 2004643402499 | I7: 1986511966113
B8: 1. | C8: 운영사업수익 | G8: 1930358967091 | I8: 1922988784772
C9: (1) | D9: 운수사업수익 | F9: 1636749394102 | H9: 1623423023974
C10: (2) | D10: 부대사업수익 | F10: 201708041379 | H10: 210258404891
C11: (3) | D11: 기타사업수익 | F11: 91901531610 | H11: 89307355907
B12: 2. | C12: 수탁사업수익 | G12: 74284435408 | I12: 63523181341
C13: (1) | D13: 운수사업수익 | F13: 34638443925 | H13: 34159419912
C14: (2) | D14: 부대사업수익 | F14: 2741859716 | H14: 2016318709
C15: (3) | D15: 기타사업수익 | F15: 153993445 | H15: 83415797
C16: (4) | D16: 대행사업수익 | F16: 36750138322 | H16: 27264026923
A17: Ⅱ. | B17: 매출원가 | G17: 2425976565726 | I17: 2398125745965
B18: 1. | C18: 운영사업원가 | F18: 2351692130318 | H18: 2334602564624
B19: 2. | C19: 수탁사업원가 | F19: 74284435408 | H19: 63523181341
C20: (1) | D20: 7호선 연장구간 | F20: 40788577545 | H20: 39282080924
C21: (2) | D21: 9호선 2-3단계 운영 | F21: 31731972382 | H21: 22435682705
C22: (3) | D22: 잠실광역환승센터 | F22: 1763885481 | H22: 1805417712
A23: III. | B23: 매출총이익(손실) | G23: -421333163227 | I23: -411613779852
A24: IV. | B24: 판매비와관리비 | G24: 111070576071 | I24: 120599802816
C25: 급여 | F25: 61925775834 | H25: 66974875603
C26: 퇴직급여 | F26: 6743896130 | H26: 6968196370
C27: 복리후생비 | F27: 9966306566 | H27: 10463772586
C28: 여비교통비 | F28: 249967171 | H28: 254210693
C29: 공공요금및제세 | F29: 1082519457 | H29: 1691582143
C30: 수도광열비 | F30: 205544602 | H30: 207339871
C31: 소모품비 | F31: 416149447 | H31: 187050336
C32: 도서인쇄비 | F32: 251942630 | H32: 255767753
C33: 임차료 | F33: 156083579 | H33: 143323894
C34: 감가상각비 | F34: 3490147736 | H34: 3337782554
C35: 무형자산상각비 | F35: 2809236378 | H35: 2480447749
C36: 수선유지비 | F36: 177849032 | H36: 241534083
... C48: 잡비 | F48: 1213235052 | H48: 1917902791
A49: V. | B49: 영업이익(손실) | G49: -532403739298 | I49: -532213582668
A50: VI. | B50: 영업외수익 | G50: 50400985333 | I50: 168415515687
C51: 이자수익 | F51: 2385498833 | H51: 6452635830
C52: 외환차익 | F52: 0 | H52: 3104006
...

Sheet #3. 운영사업원가명세서
A1: 운 영 사 업 원 가 명 세 서
A2: 제 3 기 2019년 1월 1일부터 2019년 12월 31일까지
A3: 제 2 기 2018년 1월 1일부터 2018년 12월 31일까지
A5: 서울교통공사 | H5: (단위 : 원)
B6: 과 목 | E6: 제 3 기 | G6: 제 2 기
A7: Ⅰ. | B7: 인건비 | F7: 1191508772688 | H7: 1200816424028
B8: 급여 | E8: 1077508630230 | G8: 1076428943058
B9: 퇴직급여 | E9: 114000142458 | G9: 124387480970
A10: Ⅱ. | B10: 경비 | F10: 1160183357630 | H10: 1133786140596
B11: 복리후생비 | E11: 164590592600 | G11: 168795914605
B12: 여비교통비 | E12: 751873187 | G12: 916139515
B13: 수도광열비 | E13: 192766161648 | G13: 191220002342
B14: 공공요금및제세 | E14: 15708736189 | G14: 13927004092
B15: 소모품비 | E15: 4427180584 | G15: 3232901012
B16: 도서인쇄비 | E16: 1112587543 | G16: 1143280475
B17: 임차료 | E17: 1813292330 | G17: 1745015244
B18: 감가상각비 | E18: 392433981054 | G18: 389689407159
B19: 무형자산상각비 | E19: 242320248 | G19: 177035547
B20: 수선유지비 | E20: 35892553468 | G20: 34782307561
B21: 차량유지비 | E21: 485434923 | G21: 489554809
B22: 보험료 | E22: 1155176024 | G22: 1230817498
... B32: 잡비 | E32: 14390661111 | G32: 13600177721
B33: 총계 | F33: 2351692130318 | H33: 2334602564624
F34: =F33='[1]#2. 손익계산서'!F18 -> FALSE | H34: =H33='[1]#2. 손익계산서'!H18 -> FALSE
F36: =F33='#2. 손익계산서'!F18 -> TRUE | H36: =H33='#2. 손익계산서'!H18 -> TRUE

Sheet #4. 수탁사업원가명세서
A1: 수 탁 사 업 원 가 명 세 서
A2: 제 3 기 2019년 1월 1일부터 2019년 12월 31일까지
A3: 제 2 기 2018년 1월 1일부터 2018년 12월 31일까지
A5: 서울교통공사 | H5: (단위 : 원)
B6: 과 목 | E6: 제 3 기 | G6: 제 2 기
A7: Ⅰ. | B7: 인건비 | F7: 33593473923 | H7: 24871194458
B8: 급여 | E8: 30555847967 | G8: 22566230267
B9: 퇴직급여 | E9: 3037625956 | G9: 2304964191
A10: Ⅱ. | B10: 경비 | F10: 40690961485 | H10: 38651986883
B11: 복리후생비 | E11: 5708677430 | G11: 2907002215
B12: 여비교통비 | E12: 17782276 | G12: 4132270
B13: 수도광열비 | E13: 9782112089 | G13: 4609787781
B14: 공공요금및제세 | E14: 406428021 | G14: 177714272
B15: 소모품비 | E15: 1073125983 | G15: 628303443
B16: 도서인쇄비 | E16: 47596529 | G16: 39773525
B17: 임차료 | E17: 771546925 | G17: 760291098
B18: 감가상각비 | E18: 0 | G18: 0
B19: 무형자산상각비 | E19: 0 | G19: 0
B20: 수선유지비 | E20: 705369006 | G20: 583519232
B21: 차량유지비 | E21: 3948184 | G21: 2237006
B22: 보험료 | E22: 1099849980 | G22: 0
... B32: 잡비 | E32: 577364268 | G32: 535378344
B33: 일반관리비 | E33: 0 | G33: #REF!
B34: 위탁수수료 | E34: 0 | G34: #REF!
B35: 총계 | F35: 74284435408 | H35: 63523181341
F36: =F35='[1]#2. 손익계산서'!F19 -> FALSE | H36: =H35='[1]#2. 손익계산서'!H19 -> FALSE
F38: =F35='#2. 손익계산서'!F19 -> TRUE | H38: =H35='#2. 손익계산서'!H19 -> TRUE

Sheet #5. 영업비용명세서
A1: 영 업 비 용 명 세 서
A2: 제 3 기 2019년 1월 1일부터 2019년 12월 31일까지
A3: 제 2 기 2018년 1월 1일부터 2018년 12월 31일까지
A5: 서울교통공사 | H5: (단위 : 원)
B6: 과 목 | E6: 제 3 기 | G6: 제 2 기
A7: Ⅰ. | B7: 인건비 | F7: 1260178444652 | H7: 1274759496001
B8: 급여 | E8: 1139434406064 | G8: 1143403818661
B9: 퇴직급여 | E9: 120744038588 | G9: 131355677340
A10: Ⅱ. | B10: 경비 | F10: 1276868697145 | H10: 1243966052780
B11: 복리후생비 | E11: 174556899166 | G11: 179259687191
B12: 여비교통비 | E12: 1001840358 | G12: 1170350208
B13: 수도광열비 | E13: 192971706250 | G13: 191427342213
B14: 공공요금및제세 | E14: 16791255646 | G14: 15618586235
B15: 소모품비 | E15: 4843330031 | G15: 3419951348
B16: 도서인쇄비 | E16: 1364530173 | G16: 1399048228
B17: 임차료 | E17: 1969375909 | G17: 1888339138
B18: 감가상각비 | E18: 395924128790 | G18: 393027189713
B19: 무형자산상각비 | E19: 3051556626 | G19: 2657483296
B20: 수선유지비 | E20: 36070402500 | G20: 35023841644
B21: 차량유지비 | E21: 509442999 | G21: 519797247
B22: 보험료 | E22: 1167774019 | G22: 1243477930
... B34: 수탁사업원가 | E34: 74284435408 | G34: 63523181341
B35: 총계 | F35: 2537047141797 | H35: 2518725548781
F36: =F35='[1]#2. 손익계산서'!F18 -> FALSE | H36: =H35='[1]#2. 손익계산서'!H18 -> FALSE
F38: =F35='#2. 손익계산서'!G17+'#2. 손익계산서'!G24 -> TRUE | H38: =H35='#2. 손익계산서'!I17+'#2. 손익계산서'!I24 -> TRUE

Sheet #6. 자본변동표
A1: 자 본 변 동 표
A2: 제 3 기 : 2019년 1월 1일 부터 2019년 12월 31일까지
A3: 제 2 기 : 2018년 1월 1일 부터 2018년 12월 31일까지
A4: 서울교통공사 | E4: (단위 : 원)
A5: 과 목 | B5: 자 본 금 | C5: 기타포괄손익누계액 | D5: 결 손 금 | E5: 총 계
A6: I. 2018.01.01(전기초) | B6: 19526953625013 | C6: 2832006217935 | D6: -13829344864203 | E6: 8529614978745
A7: 1. 자본금의 납입 | B7: 132281600000 | C7: - | D7: - | E7: 132281600000
A8: 2. 토지의 처분 | B8: - | C8: -689893867 | D8: - | E8: -689893867
A9: 3. 매도가능증권의 처분 | B9: - | C9: 7530770 | D9: - | E9: 7530770
A10: 4. 당기순손실 | B10: - | C10: - | D10: -538892667395 | E10: -538892667395
A11: II. 2018.12.31.(전기말) | B11: 19659235225013 | C11: 2831323854838 | D11: -14368237531598 | E11: 8122321548253
A12: III. 2019.01.01(당기초) | B12: 19659235225013 | C12: 2831323854838 | D12: -14368237531598 | E12: 8122321548253
A13: 1. 자본금의 납입 | B13: 182834500000 | C13: - | D13: - | E13: 182834500000
A14: 2. 출자전환 | B14: 834865664434 | C14: - | D14: - | E14: 834865664434
A15: 3. 매도가능증권평가이익 | B15: - | C15: 20194020 | D15: - | E15: 20194020
A16: 4. 당기순손실 | B16: - | C16: - | D16: -586467268145 | E16: -586467268145
A17: IV. 2019.12.31.(당기말) | B17: 20676935389447 | C17: 2831344048858 | D17: -14954704799743 | E17: 8553574638562

Sheet #7. 현금흐름표
A1: 현 금 흐 름 표
A2: 제 3 기 : 2019년 1월 1일 부터 2019년 12월 31일까지
A3: 제 2 기 : 2018년 1월 1일 부터 2018년 12월 31일까지
A4: 서울교통공사 | E4: (단위 : 원)
A5: 과 목 | B5: 제 3 기 | D5: 제 2 기
A6: Ⅰ. 영업활동으로인한현금흐름 | C6: -101311481782 | E6: -170032935845
A7: 1. 당기순손실 | B7: -586467268145 | D7: -538892667395
A8: 2. 현금의유출이없는비용등의가산 | B8: 539767159185 | D8: 559059327640
A9: 가.퇴직급여 | B9: 123781664544 | D9: 133660641531
A10: 나.감가상각비 | B10: 395924128790 | D10: 393027189713
A11: 다.유형자산처분손실 | B11: - | D11: 4057922
A12: 라.무형자산상각비 | B12: 3051556626 | D12: 2657483296
A13: 마.대손상각비 | B13: 5200984575 | D13: 7595948075
A14: 바.이자비용 | B14: 245762394 | D14: 319887494
A15: 사.재고자산폐기손실 | B15: - | D15: 1366165850
A16: 아.재고자산처분손실 | B16: 40484242 | D16: -
A17: 자.유형자산손상차손 | B17: 166510105 | D17: 177740352
A18: 차.유형자산폐기손실 | B18: 2186805495 | D18: 6879095457
A19: 카.무형자산손상차손 | B19: 83549254 | D19: 176802269
A20: 타.투자자산처분손실 | B20: 298343755 | D20: 5222378
A21: 파.기타의대손상각비 | B21: 8081234680 | D21: 11083982201
A22: 하.지분법평가손실 | B22: 706134725 | D22: 2105111102
A23: 3. 현금의유입이없는수익등의차감 | B23: -23882208124 | D23: -132938622351
A24: 가.폐품매각수익 | B24: 1828803148 | D24: 54010370
A25: 나.유형자산처분이익 | B25: 644493450 | D25: 2638044239
A26: 다.채무면제이익 | B26: - | D26: 706955969
A27: 라.자산수증이익 | B27: 13567301683 | D27: 123977245538
A28: 마.지분법평가이익 | B28: 7841607843 | D28: 5559907735
A29: 바.기타의대손충당금환입 | B29: - | D29: 2458500
A30: 사.잡이익 | B30: 2000 | D30: -
A31: 4. 영업활동으로인한자산부채의변동 | B31: -30729164698 | D31: -57260973739
A32: 가.매출채권의 감소(증가) | B32: 5223232023 | D32: -19645875608
A33: 나.미수금의 증가 | B33: -12120224172 | D33: -13732872365
A34: 다.미수수익의 감소(증가) | B34: -445733 | D34: 91357169
A35: 라.선급금의 증가 | B35: -4987389253 | D35: -4398742959
A36: 마.선급비용의 감소 | B36: 50806449 | D36: 442554208
A37: 바.당기법인세자산의 감소(증가) | B37: 495200356 | D37: -449541870
A38: 사.기타의당좌자산의 감소(증가) | B38: 815723014 | D38: -1139091074
A39: 아.재고자산의 감소 | B39: 1539087153 | D39: 8701623083
A40: 자.미지급금의 증가(감소) | B40: -7999546963 | D40: 64159344209
...

Sheet #8. 합계잔액시산표
A1: 합 계 잔 액 시 산 표
A3: 서울교통공사 | E3: (단위:원)
A4: 잔액 | B4: 차변 | C4: 계정과목 | D4: 대변 | E4: 잔액
A5: 3534887340 | B5: 429403554053 | C5: 현금 | D5: 425868666713 | E5: 0
A6: 0 | B6: 730352800000 | C6: 당좌예금 | D6: 730352800000 | E6: 0
A7: 26974607810 | B7: 25662020249515 | C7: 보통예금 | D7: 25635045641705 | E7: 0
A8: 3296657653 | B8: 6209155824 | C8: 기업자유예금 | D8: 2912498171 | E8: 0
A9: 158750898210 | B9: 10152049446180 | C9: 현금성자산 | D9: 9993298547970 | E9: 0
A10: 0 | B10: 141579779993 | C10: 국고보조금 | D10: 241584637437 | E10: 100004857444
A11: 0 | B11: 3217327461 | C11: 수탁자산취득보조금 | D11: 6721208074 | E11: 3503880613
A12: 76086314824 | B12: 2137486688555 | C12: 외상매출금 | D12: 2061400373731 | E12: 0
A13: 0 | B13: 386055410 | C13: 대손충당금 | D13: 14170204373 | E13: 13784148963
A14: 1915569210 | B14: 4486223740 | C14: 단기대여금 | D14: 2570654530 | E14: 0
A15: 36074228163 | B15: 220381539289 | C15: 미수금 | D15: 184307311126 | E15: 0
A16: 0 | B16: 40542500 | C16: 대손충당금 | D16: 22831912723 | E16: 22791370223
... A21: 446177534 | B21: 1342807210 | C21: 선급법인세 | D21: 896629676 | E21: 0
A22: 41697081 | B22: 41697081 | C22: 선급지방세 | D22: 0
A23: 1468617124 | B23: 148077127455 | C23: 기타의당좌자산 | D23: 146608510331 | E23: 0
A24: 52989011274 | B24: 126544066858 | C24: 저장품 | D24: 73555055584 | E24: 0
A25: 5394684008 | B25: 11783224777 | C25: 미착품 | D25: 6388540769 | E25: 0
A26: 400737620 | B26: 400737620 | C26: 매도가능증권 | D26: 0 | E26: 0
A27: 55961110540 | B27: 72036845137 | C27: 장기대여금 | D27: 16075734597 | E27: 0
A28: 19327606148 | B28: 32008415284 | C28: 지분법적용투자주식 | D28: 12680809136 | E28: 0
A29: 3520085114300 | B29: 3520085114300 | C29: 토지 | D29: 0 | E29: 0
A30: 452542702541 | B30: 508312098801 | C30: 건물 | D30: 55769396260 | E30: 0
A31: 0 | B31: 51791834179 | C31: 감가상각누계액 | D31: 350433951746 | E31: 298642117567
A32: 0 | B32: 82107638 | C32: 국고보조금 | D32: 753196107 | E32: 671088469
A33: 147325705 | B33: 202018417 | C33: 국고/감가상각누계액 | D33: 54692712 | E33: 0
A34: 92695433375 | B34: 98883693404 | C34: 기계장치 | D34: 6188260029 | E34: 0
... A116: 0 | B116: 0 | C116: 출자준비금 | D116: 1806666340 | E116: 1806666340
C117: 매도가능증권평가차손익 | D117: 20194020 | E117: 20194020
C118: 재평가잉여금 | D118: 2831323854838 | E118: 2831323854838
A119: 14368237531598 | B119: 14368237531598 | C119: 미처분이익잉여금(미처리결손금) | D119: 0 | E119: 0
A120: 0 | B120: 15747409440 | C120: 회계변경누적효과 | D120: 15747409440 | E120: 0
A121: 0 | B121: 0 | C121: 운수사업수익 | D121: 1636749394102 | E121: 1636749394102
A122: 0 | B122: 0 | C122: 부대사업수익 | D122: 201708041379 | E122: 201708041379
A123: 0 | B123: 0 | C123: 기타사업수익 | D123: 91901531610 | E123: 91901531610
A124: 0 | B124: 0 | C124: 대행사업수익 | D124: 74284435408 | E124: 74284435408
C125: 매출원가
A126: 1077508630230 | B126: 1077508630230 | C126: 급여 | D126: 0 | E126: 0
...
