Workbook
Name DATA1: #REF!
Name DATA1: #REF!
Name DATA1: #REF!
Name DATA1: #REF!
Name DATA10: #REF!
Name DATA10: #REF!
Name DATA10: #REF!
Name DATA10: #REF!
Name DATA11: #REF!
Name DATA11: #REF!
Name DATA11: #REF!
Name DATA11: #REF!
Name DATA12: #REF!
Name DATA12: #REF!
Name DATA12: #REF!
Name DATA12: #REF!
Name DATA13: #REF!
Name DATA13: #REF!
Name DATA13: #REF!
Name DATA13: #REF!
Name DATA14: #REF!
Name DATA14: #REF!
Name DATA14: #REF!
Name DATA14: #REF!
Name DATA15: #REF!
Name DATA15: #REF!
Name DATA15: #REF!
Name DATA15: #REF!
Name DATA16: #REF!
Name DATA16: #REF!
Name DATA16: #REF!
Name DATA16: #REF!
Name DATA17: #REF!
Name DATA17: #REF!
Name DATA17: #REF!
Name DATA17: #REF!
Name DATA18: #REF!
Name DATA18: #REF!
Name DATA18: #REF!
Name DATA18: #REF!
Name DATA19: #REF!
Name DATA19: #REF!
Name DATA19: #REF!
Name DATA19: #REF!
Name DATA2: #REF!
Name DATA2: #REF!
Name DATA2: #REF!
Name DATA2: #REF!
Name DATA20: #REF!
Name DATA20: #REF!
Name DATA20: #REF!
Name DATA20: #REF!
Name DATA21: #REF!
Name DATA21: #REF!
Name DATA21: #REF!
Name DATA21: #REF!
Name DATA22: #REF!
Name DATA22: #REF!
Name DATA22: #REF!
Name DATA22: #REF!

Sheet #1. 재무상태표
A1: 재 무 상 태 표
A2: 제 4 기말 2020년 12월 31일 현재
A3: 제 3 기말 2019년 12월 31일 현재
A5: 서울교통공사
B6: 과 목 | F6: 제 4 기말 (2020.12.31.) | H6: 제 3 기말 (2019.12.31.)
A7: 자 산
A8: Ⅰ. | B8: 유동자산 | G8: 238752037235 | I8: 239730101469
A9: (1) | C9: 당좌자산 | G9: 184332113183 | I9: 181346406187
D10: 현금및현금성자산 | F10: 242838910791 | H10: 192557051013
D11: (정부보조금) | F11: -125829534802 | H11: -100004857444
D12: (지자체보조금) | F12: -425740500 | H12: 0
D13: (수탁자산취득보조금) | F13: -15956707419 | H13: -3503880613
D14: 단기금융상품 | F14: 0 | H14: 0
D15: 단기대여금 | F15: 2681336330 | H15: 1915569210
D16: 매출채권 | F16: 69274257480 | H16: 76086314824
D17: (대손충당금) | F17: -18448457190 | H17: -13784148963
D18: 미수금 | F18: 52426949376 | H18: 36074228163
D19: (대손충당금) | F19: -24711628907 | H19: -22791370223
D20: 미수수익 | F20: 32317867 | H20: 445733
D21: 선급금 | F21: 669081173 | H21: 12527262561
... D25: 기타의당좌자산 | F25: 1276310332 | H25: 1468617124
A26: (2) | C26: 재고자산 | G26: 54419924052 | I26: 58383695282
D27: 저장품 | F27: 54065613925 | H27: 52989011274
D28: 미착품 | F28: 354310127 | H28: 5394684008
A29: Ⅱ. | B29: 비유동자산 | G29: 13101512002571 | I29: 12959314696015
A30: (1) | C30: 투자자산 | G30: 78569545026 | I30: 75689454308
D31: 매도가능증권 | F31: 424799200 | H31: 400737620
D32: 장기대여금 | F32: 52036045685 | H32: 55961110540
D33: 지분법적용투자주식 | F33: 26108700141 | H33: 19327606148
C34: 4. | D34: 장기금융상품
A35: (2) | C35: 유형자산 | G35: 12897905955715 | I35: 12762232922256
D36: 토지 | F36: 3517271652300 | H36: 3520085114300
D37: 건물 | F37: 460705168176 | H37: 452542702541
D38: (감가상각누계액) | F38: -308802124742 | H38: -298642117567
D39: (정부보조금) | F39: -542303342 | H39: -523762764
D40: 기계장치 | F40: 94972626027 | H40: 92695433375
D41: (감가상각누계액) | F41: -58706126412 | H41: -56525316138
D42: 선로설비 | F42: 11824344951297 | H42: 11707905628584
D43: (감가상각누계액) | F43: -4724799634006 | H43: -4504510544079
D44: (정부보조금) | F44: -92704210238 | H44: -65101252823
...

Sheet #2. 손익계산서
A1: 손 익 계 산 서
A2: 제 4 기 2020년 1월 1일부터 2020년 12월 31일까지
A3: 제 3 기 2019년 1월 1일부터 2019년 12월 31일까지
A5: 서울교통공사 | I5: (단위 : 원)
B6: 과 목 | F6: 제 4 기 | H6: 제 3 기
A7: Ⅰ. | B7: 매출액 | G7: 1559524670022 | I7: 2004643402499
B8: 1. | C8: 운영사업수익 | G8: 1469318644820 | I8: 1930358967091
C9: (1) | D9: 운수사업수익 | F9: 1193190739339 | H9: 1636749394102
C10: (2) | D10: 부대사업수익 | F10: 182975978871 | H10: 201708041379
C11: (3) | D11: 기타사업수익 | F11: 93151926610 | H11: 91901531610
B12: 2. | C12: 수탁사업수익 | G12: 90206025202 | I12: 74284435408
C13: (1) | D13: 운수사업수익 | F13: 26703961010 | H13: 34638443925
C14: (2) | D14: 부대사업수익 | F14: 2227967822 | H14: 2741859716
C15: (3) | D15: 기타사업수익 | F15: 87488579 | H15: 153993445
C16: (4) | D16: 대행사업수익 | F16: 61186607791 | H16: 36750138322
A17: Ⅱ. | B17: 매출원가 | G17: 2525060409210 | I17: 2425976565726
B18: 1. | C18: 운영사업원가 | F18: 2434854384008 | H18: 2351692130318
B19: 2. | C19: 수탁사업원가 | F19: 90206025202 | H19: 74284435408
C20: (1) | D20: 7호선 연장구간 | H20: 40788577545
C21: (2) | D21: 9호선 2-3단계 운영 | H21: 31731972382
C22: (3) | D22: 잠실광역환승센터 | H22: 1763885481
A23: III. | B23: 매출총이익(손실) | G23: -965535739188 | I23: -421333163227
A24: IV. | B24: 판매비와관리비 | G24: 124625107059 | I24: 111070576071
C25: 급여 | F25: 65459559113 | H25: 61925775834
C26: 퇴직급여 | F26: 11457550390 | H26: 6743896130
C27: 복리후생비 | F27: 9442796143 | H27: 9966306566
C28: 여비교통비 | F28: 35767231 | H28: 249967171
C29: 공공요금및제세 | F29: 1033050422 | H29: 1082519457
C30: 수도광열비 | F30: 202921216 | H30: 205544602
C31: 소모품비 | F31: 266063727 | H31: 416149447
C32: 도서인쇄비 | F32: 277408106 | H32: 251942630
C33: 임차료 | F33: 123737558 | H33: 156083579
C34: 감가상각비 | F34: 4782110468 | H34: 3490147736
C35: 무형자산상각비 | F35: 3147364107 | H35: 2809236378
C36: 수선유지비 | F36: 203098238 | H36: 177849032
... C48: 잡비 | F48: 2498206003 | H48: 1213235052
A49: V. | B49: 영업이익(손실) | G49: -1090160846247 | I49: -532403739298
A50: VI. | B50: 영업외수익 | G50: 50685169229 | I50: 50400985333
C51: 이자수익 | F51: 1426810395 | H51: 2385498833
C52: 외환차익 | F52: 0 | H52: 0
...

Sheet #3. 운영사업원가명세서
A1: 운 영 사 업 원 가 명 세 서
A2: 제 4 기 2020년 1월 1일부터 2020년 12월 31일까지
A3: 제 3 기 2019년 1월 1일부터 2019년 12월 31일까지
A5: 서울교통공사 | H5: (단위 : 원)
B6: 과 목 | E6: 제 4 기 | G6: 제 3 기
A7: Ⅰ. | B7: 인건비 | F7: 1278205913244 | H7: 1191508772688
B8: 급여 | E8: 1121910106764 | G8: 1077508630230
B9: 퇴직급여 | E9: 156295806480 | G9: 114000142458
A10: Ⅱ. | B10: 경비 | F10: 1156648470764 | H10: 1160183357630
B11: 복리후생비 | E11: 154762818622 | G11: 164590592600
B12: 여비교통비 | E12: 430849442 | G12: 751873187
B13: 수도광열비 | E13: 185993828237 | G13: 192766161648
B14: 공공요금및제세 | E14: 15916534165 | G14: 15708736189
B15: 소모품비 | E15: 4669912388 | G15: 4427180584
B16: 도서인쇄비 | E16: 677267596 | G16: 1112587543
B17: 임차료 | E17: 2389558159 | G17: 1813292330
B18: 감가상각비 | E18: 389974176072 | G18: 392433981054
B19: 무형자산상각비 | E19: 86422777 | G19: 242320248
B20: 수선유지비 | E20: 41671145502 | G20: 35892553468
B21: 차량유지비 | E21: 383107082 | G21: 485434923
B22: 보험료 | E22: 1187393010 | G22: 1155176024
... B32: 잡비 | E32: 16556868788 | G32: 14390661111
B33: 총계 | F33: 2434854384008 | H33: 2351692130318
F34: =F33='[1]#2. 손익계산서'!F18 -> FALSE | H34: =H33='[1]#2. 손익계산서'!H18 -> FALSE
F36: =F33='#2. 손익계산서'!F18 -> TRUE | H36: =H33='#2. 손익계산서'!H18 -> TRUE

Sheet #4. 수탁사업원가명세서
A1: 수 탁 사 업 원 가 명 세 서
A2: ='#3. 운영사업원가명세서'!A2:H2 -> 제 4 기 2020년 1월 1일부터 2020년 12월 31일까지
A3: ='#3. 운영사업원가명세서'!A3:H3 -> 제 3 기 2019년 1월 1일부터 2019년 12월 31일까지
A5: 서울교통공사 | H5: (단위 : 원)
B6: 과 목 | E6: 제 4 기 | G6: 제 3 기
A7: Ⅰ. | B7: 인건비 | F7: 42870691775 | H7: 33593473923
B8: 급여 | E8: 39800858920 | G8: 30555847967
B9: 퇴직급여 | E9: 3069832855 | G9: 3037625956
A10: Ⅱ. | B10: 경비 | F10: 47335333427 | H10: 40690961485
B11: 복리후생비 | E11: 6725172964 | G11: 5708677430
B12: 여비교통비 | E12: 18913200 | G12: 17782276
B13: 수도광열비 | E13: 10568220751 | G13: 9782112089
B14: 공공요금및제세 | E14: 493860389 | G14: 406428021
B15: 소모품비 | E15: 1633424618 | G15: 1073125983
B16: 도서인쇄비 | E16: 41015695 | G16: 47596529
B17: 임차료 | E17: 746258679 | G17: 771546925
B18: 감가상각비 | E18: 0 | G18: 0
B19: 무형자산상각비 | E19: 0 | G19: 0
B20: 수선유지비 | E20: 1399519454 | G20: 705369006
B21: 차량유지비 | E21: 5391990 | G21: 3948184
B22: 보험료 | E22: 873425964 | G22: 1099849980
... B34: 위탁수수료 | E34: 0 | G34: 0
B35: 총계 | F35: 90206025202 | H35: 74284435408
F36: =F35='[1]#2. 손익계산서'!F19 -> FALSE | H36: =H35='[1]#2. 손익계산서'!H19 -> FALSE
F38: =F35='#2. 손익계산서'!F19 -> TRUE | H38: =H35='#2. 손익계산서'!H19 -> TRUE

Sheet #5. 영업비용명세서
A1: 영 업 비 용 명 세 서
A2: ='#3. 운영사업원가명세서'!A2:H2 -> 제 4 기 2020년 1월 1일부터 2020년 12월 31일까지
A3: ='#3. 운영사업원가명세서'!A3:H3 -> 제 3 기 2019년 1월 1일부터 2019년 12월 31일까지
A5: 서울교통공사 | H5: (단위 : 원)
B6: 과 목 | E6: 제 4 기 | G6: 제 3 기
A7: Ⅰ. | B7: 인건비 | F7: 1355123022747 | H7: 1260178444652
B8: 급여 | E8: 1187369665877 | G8: 1139434406064
B9: 퇴직급여 | E9: 167753356870 | G9: 120744038588
A10: Ⅱ. | B10: 경비 | F10: 1294562493522 | H10: 1276868697145
B11: 복리후생비 | E11: 164205614765 | G11: 174556899166
B12: 여비교통비 | E12: 466616673 | G12: 1001840358
B13: 수도광열비 | E13: 186196749453 | G13: 192971706250
B14: 공공요금및제세 | E14: 16949584587 | G14: 16791255646
B15: 소모품비 | E15: 4935976115 | G15: 4843330031
B16: 도서인쇄비 | E16: 954675702 | G16: 1364530173
B17: 임차료 | E17: 2513295717 | G17: 1969375909
B18: 감가상각비 | E18: 394756286540 | G18: 395924128790
B19: 무형자산상각비 | E19: 3233786884 | G19: 3051556626
B20: 수선유지비 | E20: 41874243740 | G20: 36070402500
B21: 차량유지비 | E21: 394902659 | G21: 509442999
B22: 보험료 | E22: 1199238639 | G22: 1167774019
... B34: 수탁사업원가 | E34: 90206025202 | G34: 74284435408
B35: 총계 | F35: 2649685516269 | H35: 2537047141797
F36: =F35='[1]#2. 손익계산서'!F18 -> FALSE | H36: =H35='[1]#2. 손익계산서'!H18 -> FALSE
F38: =F35='#2. 손익계산서'!G17+'#2. 손익계산서'!G24 -> TRUE | H38: =H35='#2. 손익계산서'!I17+'#2. 손익계산서'!I24 -> TRUE

Sheet #6. 자본변동표
A1: 자 본 변 동 표
A2: 제 4 기 : 2020년 1월 1일 부터 2020년 12월 31일까지
A3: 제 3 기 : 2019년 1월 1일 부터 2019년 12월 31일까지
A4: 서울교통공사 | E4: (단위 : 원)
A5: 과 목 | B5: 자 본 금 | C5: 기타포괄손익누계액 | D5: 결 손 금 | E5: 총 계
A6: 2019.01.01(전기초)(수정전) | B6: 19659235225013 | C6: 2831323854838 | D6: -14368237531598 | E6: 8122321548253
A7: 전기오류수정 | B7: 0 | C7: -685180372871 | D7: 0 | E7: -685180372871
A8: 2019.01.01(전기초)(수정후) | B8: 19659235225013 | C8: 2146143481967 | D8: -14368237531598 | E8: 7437141175382
A9: 1. 현금출자 | B9: 182834500000 | C9: - | D9: - | E9: 182834500000
A10: 2. 현물출자 | B10: 834865664434 | C10: - | D10: - | E10: 834865664434
A11: 3. 매도가능증권평가이익 | B11: - | C11: 20194020 | D11: - | E11: 20194020
A12: 4. 당기순손실 | B12: - | C12: - | D12: -586467268145 | E12: -586467268145
A13: 2019.12.31.(전기말) | B13: 20676935389447 | C13: 2146163675987 | D13: -14954704799743 | E13: 7868394265691
A14: 2020.01.01(당기초) | B14: 20676935389447 | C14: 2146163675987 | D14: -14954704799743 | E14: 7868394265691
A15: 1. 현금출자 | B15: 323912762000 | C15: - | D15: - | E15: 323912762000
A16: 2. 토지재평가차익 | C16: 8199004618 | D16: - | E16: 8199004618
A17: 3. 매도가능증권평가이익 | B17: - | C17: 24061580 | D17: - | E17: 24061580
A18: 4. 지분법자본변동 | C18: 337110 | E18: 337110
A19: 5. 당기순손실 | B19: - | C19: - | D19: -1113736562637 | E19: -1113736562637
A20: 2020.12.31.(당기말) | B20: 21000848151447 | C20: 2154387079295 | D20: -16068441362380 | E20: 7086793868362
E23: =E20='#1. 재무상태표'!G117 -> TRUE

Sheet #7. 현금흐름표
A1: 현 금 흐 름 표
A2: 제 4 기 : 2020년 1월 1일 부터 2020년 12월 31일까지
A3: 제 3 기 : 2019년 1월 1일 부터 2019년 12월 31일까지
A4: 서울교통공사 | E4: (단위 : 원)
A5: 과 목 | B5: 제 4 기 | D5: 제 3 기
A6: Ⅰ. 영업활동으로인한현금흐름 | C6: -596182154607 | E6: -101311481782
A7: 1. 당기순손실 | B7: -1113736562637 | D7: -586467268145
A8: 2. 현금의유출이없는비용등의가산 | B8: 615758162195 | D8: 539767159185
A9: 가.퇴직급여 | B9: 170823189725 | D9: 123781664544
A10: 나.감가상각비 | B10: 394756286540 | D10: 395924128790
A11: 다.유형자산처분손실 | B11: 1383601340 | D11: 0
A12: 라.무형자산상각비 | B12: 3233786884 | D12: 3051556626
A13: 마.대손상각비 | B13: 7263897707 | D13: 5200984575
A14: 바.이자비용 | B14: 25689817357 | D14: 245762394
A15: 사.재고자산폐기손실 | B15: 81822507 | D15: 0
A16: 아.재고자산처분손실 | B16: 0 | D16: 40484242
A17: 자.유형자산손상차손 | B17: 2800705151 | D17: 166510105
A18: 차.유형자산폐기손실 | B18: 7797858300 | D18: 2186805495
... A53: 처.배당금의 수령 | B53: 1488000000 | D53: 0
A54: Ⅱ. 투자활동으로인한현금흐름 | C54: -492884836015 | E54: -435164227211
A55: 1. 투자활동으로인한현금유입액 | B55: 141563554105 | D55: 29144330134
A56: 가.단기대여금의 감소 | B56: 1915569210 | D56: 2570654530
A57: 나.장기대여금의 감소 | B57: 9442020317 | D57: 16075734597
A58: 다.지분법적용투자주식의 처분 | B58: 0 | D58: 7146909915
A59: 라.토지의 처분 | B59: 1803913560 | D59: 0
A60: 마.보증금의 감소 | B60: 0 | D60: 85000000
A61: 바.기타의비유동자산의 감소 | B61: 3185042352 | D61: 3266031092
A62: 사.정부보조금의 수령 | B62: 105491778699 | D62: 0
A63: 아.지자체보조금의 수령 | B63: 1532740000 | D63: 0
A64: 자.수탁자산취득보조금의 수령 | B64: 18192489967 | D64: 0
A65: 2. 투자활동으로인한현금유출액 | B65: -634448390120 | D65: -464308557345
A66: 가.장기대여금의 증가 | B66: 8198291792 | D66: 13291816795
... A80: 거.수탁자산취득보조금의 상환 | B80: 135287775 | D80: 0
A81: Ⅲ. 재무활동으로인한현금흐름 | C81: 1139348850400 | E81: 455972296151
A82: 1. 재무활동으로인한현금유입액 | B82: 2291748850400 | D82: 717520890792
A83: 가.단기차입금의 차입 | B83: 1260000000000 | D83: 0
A84: 나.공채의 발행 | B84: 0 | D84: 123375730000
A85: 다.사채의 발행 | B85: 707836088400 | D85: 179959688400
A86: 라.장기차입금의 차입 | B86: 0 | D86: 175000000000
A87: 마.유동성장기부채의 차입 | B87: 0 | D87: 0
...

Sheet #8. 합계잔액시산표
A1: 합 계 잔 액 시 산 표
A3: 서울교통공사 | E3: (단위:원)
A4: 잔액 | B4: 차변 | C4: 계정과목 | D4: 대변 | E4: 잔액
A5: 2807377200 | B5: 250045462050 | C5: 현금 | D5: 247238084850 | E5: 0
A6: 0 | B6: 960439139708 | C6: 당좌예금 | D6: 960439139708 | E6: 0
A7: 284021716 | B7: 491861962038 | C7: 보통예금 | D7: 491577940322 | E7: 0
A8: 45281265197 | B8: 24625116539327 | C8: 기업자유예금 | D8: 24579835274130 | E8: 0
A9: 194466246678 | B9: 12560057733493 | C9: 현금성자산 | D9: 12365591486815 | E9: 0
A10: 0 | B10: 127378069027 | C10: 국고보조금 | D10: 253633344329 | E10: 126255275302
A11: 0 | B11: 7748432180 | C11: 수탁자산취득보조금 | D11: 23705139599 | E11: 15956707419
A12: 0 | B12: 30000000000 | C12: 단기투자자산 | D12: 30000000000 | E12: 0
A13: 69274257480 | B13: 1687075728106 | C13: 외상매출금 | D13: 1617801470626 | E13: 0
A14: 0 | B14: 825804762 | C14: 대손충당금 | D14: 19274261952 | E14: 18448457190
A15: 2681336330 | B15: 4596905540 | C15: 단기대여금 | D15: 1915569210 | E15: 0
A16: 52426949376 | B16: 105416498489 | C16: 미수금 | D16: 52989549113 | E16: 0
... A112: 0 | B112: 0 | C112: 기타의유동부채 | D112: 11728399207 | E112: 11728399207
A113: 0 | B113: 540000000000 | C113: 사채 | D113: 1978000000000 | E113: 1438000000000 | G113: =SUM(E113:E124)-A114-A118-A121 -> 4845154595212
A114: 253082766 | B114: 295806271 | C114: 사채발행차금 | D114: 42723505 | E114: 0
A115: 0 | B115: 310500000000 | C115: 공채 | D115: 1732809320000 | E115: 1422309320000
A116: 0 | B116: 317400000000 | C116: 장기차입금 | D116: 317400000000 | E116: 0
A117: 0 | B117: 2941483947 | C117: 장기미지급금 | D117: 4315757720 | E117: 1374273773
A118: 30593181 | B118: 155947751 | C118: 현재가치할인차금 | D118: 125354570 | E118: 0
A119: 0 | B119: 41812723277 | C119: 장기미지급비용 | D119: 107092036543 | E119: 65279313266
A120: 0 | B120: 93523114265 | C120: 퇴직급여충당부채 | D120: 1240321513098 | E120: 1146798398833
A121: 290831970 | B121: 294417770 | C121: 국민연금전환금 | D121: 3585800 | E121: 0
A122: 0 | B122: 7725908783 | C122: 장기선수수익 | D122: 38316170146 | E122: 30590261363
A123: 0 | B123: 49800364549 | C123: 기타의비유동부채 | D123: 116573874046 | E123: 66773509497
B124: 0 | C124: 이연법인세부채 | D124: 674604026397 | E124: 674604026397
A125: 0 | B125: 400000000 | C125: 자본금 | D125: 20999441485107 | E125: 20999041485107
A126: 0 | B126: 0 | C126: 출자준비금 | D126: 1806666340 | E126: 1806666340
A127: 0 | B127: 0 | C127: 매도가능증권평가차손익 | D127: 44255600 | E127: 44255600
A128: 0 | B128: 676981368253 | C128: 재평가잉여금 | D128: 2831323854838 | E128: 2154342486585
C129: 지분법자본변동 | D129: 337110 | E129: 337110
A130: 14954704799743 | B130: 14954704799743 | C130: 미처분이익잉여금 | D130: 0 | E130: 0
A131: 0 | B131: 0 | C131: 운수사업수익 | D131: 1193190739339 | E131: 1193190739339
A132: 0 | B132: 0 | C132: 부대사업수익 | D132: 182975978871 | E132: 182975978871
A133: 0 | B133: 0 | C133: 기타사업수익 | D133: 93151926610 | E133: 93151926610
A134: 0 | B134: 0 | C134: 대행사업수익 | D134: 90206025202 | E134: 90206025202
C135: 매출원가
A136: 959689254264 | B136: 959689254264 | C136: 급여 | D136: 0 | E136: 0
...
